<?xml version="1.0" ?>
<robot name="IRB1200H_7_70_STD">

<link name="base_link">
  <inertial>
    <origin xyz="-0.02363502115054783 0.0004753411198600945 0.11218944380427573" rpy="0 0 0"/>
    <mass value="83.56281675930377"/>
    <inertia ixx="0.579272" iyy="0.781174" izz="0.698162" ixy="0.004319" iyz="-0.001283" ixz="-0.00506"/>
  </inertial>
  <visual>
    <origin xyz="0 0 0" rpy="0 0 0"/>
    <geometry>
      <mesh filename="meshes/base_link.stl" scale="0.001 0.001 0.001"/>
    </geometry>
  </visual>
  <collision>
    <origin xyz="0 0 0" rpy="0 0 0"/>
    <geometry>
      <mesh filename="meshes/base_link.stl" scale="0.001 0.001 0.001"/>
    </geometry>
  </collision>
</link>

<link name="link_1">
  <inertial>
    <origin xyz="-0.0032574143563410597 0.0004228928818921135 0.10229437430585911" rpy="0 0 0"/>
    <mass value="47.62183211112662"/>
    <inertia ixx="0.595344" iyy="0.377408" izz="0.433985" ixy="-0.000147" iyz="0.000705" ixz="-0.004382"/>
  </inertial>
  <visual>
    <origin xyz="-0.0 -0.0 -0.219" rpy="0 0 0"/>
    <geometry>
      <mesh filename="meshes/link_1.stl" scale="0.001 0.001 0.001"/>
    </geometry>
  </visual>
  <collision>
    <origin xyz="-0.0 -0.0 -0.219" rpy="0 0 0"/>
    <geometry>
      <mesh filename="meshes/link_1.stl" scale="0.001 0.001 0.001"/>
    </geometry>
  </collision>
</link>

<link name="link_2">
  <inertial>
    <origin xyz="-0.009944347609699757 0.06037825705225541 0.16624234768686852" rpy="0 0 0"/>
    <mass value="54.93093636945645"/>
    <inertia ixx="1.322479" iyy="1.146829" izz="0.3246" ixy="0.000481" iyz="6e-05" ixz="-0.006609"/>
  </inertial>
  <visual>
    <origin xyz="-0.0 0.0615 -0.3991" rpy="0 0 0"/>
    <geometry>
      <mesh filename="meshes/link_2.stl" scale="0.001 0.001 0.001"/>
    </geometry>
  </visual>
  <collision>
    <origin xyz="-0.0 0.0615 -0.3991" rpy="0 0 0"/>
    <geometry>
      <mesh filename="meshes/link_2.stl" scale="0.001 0.001 0.001"/>
    </geometry>
  </collision>
</link>

<link name="link_3">
  <inertial>
    <origin xyz="0.04273309398912055 0.06101103306372527 0.035299755142302436" rpy="0 0 0"/>
    <mass value="38.854634298936446"/>
    <inertia ixx="0.127707" iyy="0.302841" izz="0.263122" ixy="6.1e-05" iyz="-8.6e-05" ixz="-0.012088"/>
  </inertial>
  <visual>
    <origin xyz="-0.0 0.061 -0.7491" rpy="0 0 0"/>
    <geometry>
      <mesh filename="meshes/link_3.stl" scale="0.001 0.001 0.001"/>
    </geometry>
  </visual>
  <collision>
    <origin xyz="-0.0 0.061 -0.7491" rpy="0 0 0"/>
    <geometry>
      <mesh filename="meshes/link_3.stl" scale="0.001 0.001 0.001"/>
    </geometry>
  </collision>
</link>

<link name="link_4">
  <inertial>
    <origin xyz="0.09376827741240087 0.0016293023500022993 0.0010874229942521296" rpy="0 0 0"/>
    <mass value="14.103514853516494"/>
    <inertia ixx="0.029406" iyy="0.057716" izz="0.061956" ixy="-0.001377" iyz="-1.2e-05" ixz="0.000468"/>
  </inertial>
  <visual>
    <origin xyz="-0.1655 0.00012 -0.791099" rpy="0 0 0"/>
    <geometry>
      <mesh filename="meshes/link_4.stl" scale="0.001 0.001 0.001"/>
    </geometry>
  </visual>
  <collision>
    <origin xyz="-0.1655 0.00012 -0.791099" rpy="0 0 0"/>
    <geometry>
      <mesh filename="meshes/link_4.stl" scale="0.001 0.001 0.001"/>
    </geometry>
  </collision>
</link>

<link name="link_5">
  <inertial>
    <origin xyz="0.013848200109173203 -0.027811016104562186 5.4563116480554896e-05" rpy="0 0 0"/>
    <mass value="4.542326346976594"/>
    <inertia ixx="0.003479" iyy="0.008928" izz="0.007834" ixy="-0.000177" iyz="-4e-06" ixz="1.2e-05"/>
  </inertial>
  <visual>
    <origin xyz="-0.351 -0.025379 -0.7911" rpy="0 0 0"/>
    <geometry>
      <mesh filename="meshes/link_5.stl" scale="0.001 0.001 0.001"/>
    </geometry>
  </visual>
  <collision>
    <origin xyz="-0.351 -0.025379 -0.7911" rpy="0 0 0"/>
    <geometry>
      <mesh filename="meshes/link_5.stl" scale="0.001 0.001 0.001"/>
    </geometry>
  </collision>
</link>

<link name="link_6">
  <inertial>
    <origin xyz="0.002845591460718222 3.5148072682996196e-07 -0.00036679995380684005" rpy="0 0 0"/>
    <mass value="0.036681809664465305"/>
    <inertia ixx="1e-05" iyy="5e-06" izz="5e-06" ixy="0.0" iyz="-0.0" ixz="-0.0"/>
  </inertial>
  <visual>
    <origin xyz="-0.4365 4e-06 -0.7911" rpy="0 0 0"/>
    <geometry>
      <mesh filename="meshes/link_6.stl" scale="0.001 0.001 0.001"/>
    </geometry>
  </visual>
  <collision>
    <origin xyz="-0.4365 4e-06 -0.7911" rpy="0 0 0"/>
    <geometry>
      <mesh filename="meshes/link_6.stl" scale="0.001 0.001 0.001"/>
    </geometry>
  </collision>
</link>

<joint name="joint_1" type="revolute">
  <origin xyz="0.0 0.0 0.219" rpy="0 0 0"/>
  <parent link="base_link"/>
  <child link="link_1"/>
  <axis xyz="0.0 0.0 1.0"/>
  <limit lower="-2.9671" upper="2.9671" effort="0" velocity="5.0265" />
</joint>

<joint name="joint_2" type="revolute">
  <origin xyz="0.0 -0.0615 0.1801" rpy="0 0 0"/>
  <parent link="link_1"/>
  <child link="link_2"/>
  <axis xyz="0.0 -1.0 0.0"/>
  <limit lower="-1.7453" upper="2.2689" effort="0" velocity="3.9095" />
</joint>

<joint name="joint_3" type="revolute">
  <origin xyz="0.0 0.0005 0.35" rpy="0 0 0"/>
  <parent link="link_2"/>
  <child link="link_3"/>
  <axis xyz="0.0 -1.0 0.0"/>
  <limit lower="-3.4907" upper="1.2217" effort="0" velocity="5.1836" />
</joint>

<joint name="joint_4" type="revolute">
  <origin xyz="0.1655 0.06088 0.041999" rpy="0 0 0"/>
  <parent link="link_3"/>
  <child link="link_4"/>
  <axis xyz="-1.0 0.0 1.7e-05"/>
  <limit lower="-4.7124" upper="4.7124" effort="0" velocity="6.9813" />
</joint>

<joint name="joint_5" type="revolute">
  <origin xyz="0.1855 0.025499 1e-06" rpy="0 0 0"/>
  <parent link="link_4"/>
  <child link="link_5"/>
  <axis xyz="0.0 -1.0 0.0"/>
  <limit lower="-2.2689" upper="2.2689" effort="0" velocity="7.0686" />
</joint>

<joint name="joint_6" type="revolute">
  <origin xyz="0.0855 -0.025383 0.0" rpy="0 0 0"/>
  <parent link="link_5"/>
  <child link="link_6"/>
  <axis xyz="1.0 0.0 0.0"/>
  <limit lower="-6.9813" upper="6.9813" effort="0" velocity="10.4719" />
</joint>

<link name="flange">
</link>

<joint name="joint_6-flange" type="fixed">
  <origin xyz="0 0 0" rpy="0 1.57 0"/>
  <parent link="link_6"/>
  <child link="flange"/>
</joint>

<link name="tool0">
</link>

<joint name="flange-tool0" type="fixed">
  <origin xyz="0 0 0" rpy="0 0 0"/>
  <parent link="flange"/>
  <child link="tool0"/>
</joint>

</robot>