<?xml version="1.0" ?>
<robot name="CRB15000_12_127">

<link name="base_link">
  <inertial>
    <origin xyz="-0.0011656606666003635 -0.00011127786600189429 0.09856917133626068" rpy="0 0 0"/>
    <mass value="43.32183419472872"/>
    <inertia ixx="0.254824" iyy="0.26074" izz="0.191484" ixy="-0.000567" iyz="-0.000372" ixz="-0.003894"/>
  </inertial>
  <visual>
    <origin xyz="0 0 0" rpy="0 0 0"/>
    <geometry>
      <mesh filename="meshes/base_link.stl" scale="0.001 0.001 0.001"/>
    </geometry>
  </visual>
  <collision>
    <origin xyz="0 0 0" rpy="0 0 0"/>
    <geometry>
      <mesh filename="meshes/base_link.stl" scale="0.001 0.001 0.001"/>
    </geometry>
  </collision>
</link>

<link name="CRB15000_12kg_127_Omnicore_rev00_LINK01_CAD_1">
  <inertial>
    <origin xyz="-2.953604310759913e-07 0.004410241344758071 0.135757118326414" rpy="0 0 0"/>
    <mass value="41.02562588128756"/>
    <inertia ixx="0.236926" iyy="0.184428" izz="0.192336" ixy="-1e-06" iyz="-0.003705" ixz="0.0"/>
  </inertial>
  <visual>
    <origin xyz="0.0 -0.0 -0.181677" rpy="0 0 0"/>
    <geometry>
      <mesh filename="meshes/CRB15000_12kg_127_Omnicore_rev00_LINK01_CAD_1.stl" scale="0.001 0.001 0.001"/>
    </geometry>
  </visual>
  <collision>
    <origin xyz="0.0 -0.0 -0.181677" rpy="0 0 0"/>
    <geometry>
      <mesh filename="meshes/CRB15000_12kg_127_Omnicore_rev00_LINK01_CAD_1.stl" scale="0.001 0.001 0.001"/>
    </geometry>
  </collision>
</link>

<link name="CRB15000_12kg_127_Omnicore_rev00_LINK02_CAD_1">
  <inertial>
    <origin xyz="1.1298944563353409e-07 -0.05432141440967557 0.31995399683651154" rpy="0 0 0"/>
    <mass value="70.93334832681374"/>
    <inertia ixx="4.564663" iyy="4.624733" izz="0.149362" ixy="0.0" iyz="-0.067787" ixz="-2e-06"/>
  </inertial>
  <visual>
    <origin xyz="-0.0 0.09615 -0.338" rpy="0 0 0"/>
    <geometry>
      <mesh filename="meshes/CRB15000_12kg_127_Omnicore_rev00_LINK02_CAD_1.stl" scale="0.001 0.001 0.001"/>
    </geometry>
  </visual>
  <collision>
    <origin xyz="-0.0 0.09615 -0.338" rpy="0 0 0"/>
    <geometry>
      <mesh filename="meshes/CRB15000_12kg_127_Omnicore_rev00_LINK02_CAD_1.stl" scale="0.001 0.001 0.001"/>
    </geometry>
  </collision>
</link>

<link name="CRB15000_12kg_127_Omnicore_rev00_LINK03_CAD_1">
  <inertial>
    <origin xyz="0.012899169793532008 0.09403704088620901 0.024906948840264675" rpy="0 0 0"/>
    <mass value="26.381731962312585"/>
    <inertia ixx="0.135784" iyy="0.109626" izz="0.102204" ixy="0.002633" iyz="0.005085" ixz="-0.024959"/>
  </inertial>
  <visual>
    <origin xyz="-0.0 0.0863 -1.045" rpy="0 0 0"/>
    <geometry>
      <mesh filename="meshes/CRB15000_12kg_127_Omnicore_rev00_LINK03_CAD_1.stl" scale="0.001 0.001 0.001"/>
    </geometry>
  </visual>
  <collision>
    <origin xyz="-0.0 0.0863 -1.045" rpy="0 0 0"/>
    <geometry>
      <mesh filename="meshes/CRB15000_12kg_127_Omnicore_rev00_LINK03_CAD_1.stl" scale="0.001 0.001 0.001"/>
    </geometry>
  </collision>
</link>

<link name="CRB15000_12kg_127_Omnicore_rev00_LINK04_CAD_1">
  <inertial>
    <origin xyz="0.19839211176894214 0.05675429813708446 5.228426895875771e-07" rpy="0 0 0"/>
    <mass value="27.702812566356673"/>
    <inertia ixx="0.097386" iyy="0.497655" izz="0.555153" ixy="-0.13931" iyz="1e-06" ixz="6e-06"/>
  </inertial>
  <visual>
    <origin xyz="-0.097 0.0 -1.155" rpy="0 0 0"/>
    <geometry>
      <mesh filename="meshes/CRB15000_12kg_127_Omnicore_rev00_LINK04_CAD_1.stl" scale="0.001 0.001 0.001"/>
    </geometry>
  </visual>
  <collision>
    <origin xyz="-0.097 0.0 -1.155" rpy="0 0 0"/>
    <geometry>
      <mesh filename="meshes/CRB15000_12kg_127_Omnicore_rev00_LINK04_CAD_1.stl" scale="0.001 0.001 0.001"/>
    </geometry>
  </collision>
</link>

<link name="CRB15000_12kg_127_Omnicore_rev00_LINK05_CAD_1">
  <inertial>
    <origin xyz="-0.014714796269106878 -0.07856678438355963 0.042754343919074955" rpy="0 0 0"/>
    <mass value="23.63754989165508"/>
    <inertia ixx="0.08996" iyy="0.106457" izz="0.085163" ixy="0.001414" iyz="-0.004125" ixz="0.012972"/>
  </inertial>
  <visual>
    <origin xyz="-0.534 -0.0745 -1.155" rpy="0 0 0"/>
    <geometry>
      <mesh filename="meshes/CRB15000_12kg_127_Omnicore_rev00_LINK05_CAD_1.stl" scale="0.001 0.001 0.001"/>
    </geometry>
  </visual>
  <collision>
    <origin xyz="-0.534 -0.0745 -1.155" rpy="0 0 0"/>
    <geometry>
      <mesh filename="meshes/CRB15000_12kg_127_Omnicore_rev00_LINK05_CAD_1.stl" scale="0.001 0.001 0.001"/>
    </geometry>
  </collision>
</link>

<link name="CRB15000_12kg_127_Omnicore_rev00_LINK06_CAD_1">
  <inertial>
    <origin xyz="0.012650716328436618 0.00023981671877066696 -0.00034191150328566344" rpy="0 0 0"/>
    <mass value="1.1500367505463056"/>
    <inertia ixx="0.001012" iyy="0.000597" izz="0.000601" ixy="-1e-06" iyz="-5e-06" ixz="1e-06"/>
  </inertial>
  <visual>
    <origin xyz="-0.6025 0.0 -1.235" rpy="0 0 0"/>
    <geometry>
      <mesh filename="meshes/CRB15000_12kg_127_Omnicore_rev00_LINK06_CAD_1.stl" scale="0.001 0.001 0.001"/>
    </geometry>
  </visual>
  <collision>
    <origin xyz="-0.6025 0.0 -1.235" rpy="0 0 0"/>
    <geometry>
      <mesh filename="meshes/CRB15000_12kg_127_Omnicore_rev00_LINK06_CAD_1.stl" scale="0.001 0.001 0.001"/>
    </geometry>
  </collision>
</link>

<joint name="j1" type="continuous">
  <origin xyz="0.0 0.0 0.181677" rpy="0 0 0"/>
  <parent link="base_link"/>
  <child link="CRB15000_12kg_127_Omnicore_rev00_LINK01_CAD_1"/>
  <axis xyz="-0.0 0.0 1.0"/>
</joint>

<joint name="j2" type="continuous">
  <origin xyz="0.0 -0.09615 0.156323" rpy="0 0 0"/>
  <parent link="CRB15000_12kg_127_Omnicore_rev00_LINK01_CAD_1"/>
  <child link="CRB15000_12kg_127_Omnicore_rev00_LINK02_CAD_1"/>
  <axis xyz="0.0 -1.0 -0.0"/>
</joint>

<joint name="j3" type="continuous">
  <origin xyz="0.0 0.00985 0.707" rpy="0 0 0"/>
  <parent link="CRB15000_12kg_127_Omnicore_rev00_LINK02_CAD_1"/>
  <child link="CRB15000_12kg_127_Omnicore_rev00_LINK03_CAD_1"/>
  <axis xyz="0.0 -1.0 -0.0"/>
</joint>

<joint name="j4" type="continuous">
  <origin xyz="0.097 0.0863 0.11" rpy="0 0 0"/>
  <parent link="CRB15000_12kg_127_Omnicore_rev00_LINK03_CAD_1"/>
  <child link="CRB15000_12kg_127_Omnicore_rev00_LINK04_CAD_1"/>
  <axis xyz="-1.0 0.0 -0.0"/>
</joint>

<joint name="j5" type="continuous">
  <origin xyz="0.437 0.0745 0.0" rpy="0 0 0"/>
  <parent link="CRB15000_12kg_127_Omnicore_rev00_LINK04_CAD_1"/>
  <child link="CRB15000_12kg_127_Omnicore_rev00_LINK05_CAD_1"/>
  <axis xyz="0.0 -1.0 0.0"/>
</joint>

<joint name="j6" type="continuous">
  <origin xyz="0.0685 -0.0745 0.08" rpy="0 0 0"/>
  <parent link="CRB15000_12kg_127_Omnicore_rev00_LINK05_CAD_1"/>
  <child link="CRB15000_12kg_127_Omnicore_rev00_LINK06_CAD_1"/>
  <axis xyz="-1.0 0.0 -0.0"/>
</joint>

</robot>