<?xml version="1.0" ?>
<robot name="Irbpc_1000_IRC5_rev02_CAD">

<link name="base_link">
  <inertial>
    <origin xyz="0.9250238746065403 -0.00012294956192347508 0.21441615376360887" rpy="0 0 0"/>
    <mass value="1310.5292686537296"/>
    <inertia ixx="51.101771" iyy="82.104533" izz="91.002161" ixy="-0.063507" iyz="-0.013079" ixz="-0.950218"/>
  </inertial>
  <visual>
    <origin xyz="0 0 0" rpy="0 0 0"/>
    <geometry>
      <mesh filename="meshes/base_link.stl" scale="0.001 0.001 0.001"/>
    </geometry>
  </visual>
  <collision>
    <origin xyz="0 0 0" rpy="0 0 0"/>
    <geometry>
      <mesh filename="meshes/base_link.stl" scale="0.001 0.001 0.001"/>
    </geometry>
  </collision>
</link>

<link name="Irbpc_1000_IRC5_rev02_Arm1000C_CAD_1">
  <inertial>
    <origin xyz="-8.440137477805365e-11 0.003669945663484575 0.30039075717668395" rpy="0 0 0"/>
    <mass value="1619.5073115051896"/>
    <inertia ixx="264.813381" iyy="496.861576" izz="552.616166" ixy="0.000972" iyz="1.35508" ixz="-0.0"/>
  </inertial>
  <visual>
    <origin xyz="-1.013 -0.0 -0.481" rpy="0 0 0"/>
    <geometry>
      <mesh filename="meshes/Irbpc_1000_IRC5_rev02_Arm1000C_CAD_1.stl" scale="0.001 0.001 0.001"/>
    </geometry>
  </visual>
  <collision>
    <origin xyz="-1.013 -0.0 -0.481" rpy="0 0 0"/>
    <geometry>
      <mesh filename="meshes/Irbpc_1000_IRC5_rev02_Arm1000C_CAD_1.stl" scale="0.001 0.001 0.001"/>
    </geometry>
  </collision>
</link>

<joint name="j1" type="continuous">
  <origin xyz="1.013 0.0 0.481" rpy="0 0 0"/>
  <parent link="base_link"/>
  <child link="Irbpc_1000_IRC5_rev02_Arm1000C_CAD_1"/>
  <axis xyz="-0.0 -0.0 -1.0"/>
</joint>

</robot>