<?xml version="1.0" ?>
<robot name="IRB1520ID_4_150">

<link name="base_link">
  <inertial>
    <origin xyz="-0.11951641673861603 0.0009257248980786925 0.08689967160381512" rpy="0 0 0"/>
    <mass value="173.23686098491044"/>
    <inertia ixx="1.85753" iyy="4.725389" izz="5.772748" ixy="0.001362" iyz="-0.001328" ixz="0.047514"/>
  </inertial>
  <visual>
    <origin xyz="0 0 0" rpy="0 0 0"/>
    <geometry>
      <mesh filename="meshes/base_link.stl" scale="0.001 0.001 0.001"/>
    </geometry>
  </visual>
  <collision>
    <origin xyz="0 0 0" rpy="0 0 0"/>
    <geometry>
      <mesh filename="meshes/base_link.stl" scale="0.001 0.001 0.001"/>
    </geometry>
  </collision>
</link>

<link name="link_1">
  <inertial>
    <origin xyz="0.05707281488826015 0.0006025778841929872 0.13293060234197612" rpy="0 0 0"/>
    <mass value="140.431105262512"/>
    <inertia ixx="2.48605" iyy="3.333637" izz="2.728491" ixy="-0.228315" iyz="-0.276475" ixz="-0.925441"/>
  </inertial>
  <visual>
    <origin xyz="0.0 0.0 -0.179" rpy="0 0 0"/>
    <geometry>
      <mesh filename="meshes/link_1.stl" scale="0.001 0.001 0.001"/>
    </geometry>
  </visual>
  <collision>
    <origin xyz="0.0 0.0 -0.179" rpy="0 0 0"/>
    <geometry>
      <mesh filename="meshes/link_1.stl" scale="0.001 0.001 0.001"/>
    </geometry>
  </collision>
</link>

<link name="link_2">
  <inertial>
    <origin xyz="0.0007044579416419228 -0.03149605796477184 0.29006399785734144" rpy="0 0 0"/>
    <mass value="41.09408994963129"/>
    <inertia ixx="1.373064" iyy="1.407108" izz="0.070327" ixy="0.000339" iyz="0.044252" ixz="-0.003017"/>
  </inertial>
  <visual>
    <origin xyz="-0.16 0.101 -0.453" rpy="0 0 0"/>
    <geometry>
      <mesh filename="meshes/link_2.stl" scale="0.001 0.001 0.001"/>
    </geometry>
  </visual>
  <collision>
    <origin xyz="-0.16 0.101 -0.453" rpy="0 0 0"/>
    <geometry>
      <mesh filename="meshes/link_2.stl" scale="0.001 0.001 0.001"/>
    </geometry>
  </collision>
</link>

<link name="link_3">
  <inertial>
    <origin xyz="0.06548004242621241 0.1344685694664799 0.07826527979937392" rpy="0 0 0"/>
    <mass value="87.68237861319876"/>
    <inertia ixx="0.971776" iyy="1.045833" izz="0.839198" ixy="-0.018707" iyz="-0.003599" ixz="-0.330412"/>
  </inertial>
  <visual>
    <origin xyz="-0.16 0.121 -1.043" rpy="0 0 0"/>
    <geometry>
      <mesh filename="meshes/link_3.stl" scale="0.001 0.001 0.001"/>
    </geometry>
  </visual>
  <collision>
    <origin xyz="-0.16 0.121 -1.043" rpy="0 0 0"/>
    <geometry>
      <mesh filename="meshes/link_3.stl" scale="0.001 0.001 0.001"/>
    </geometry>
  </collision>
</link>

<link name="link_4">
  <inertial>
    <origin xyz="0.2563461184029021 0.05731755029377212 6.253808667189276e-05" rpy="0 0 0"/>
    <mass value="21.10958519516661"/>
    <inertia ixx="0.082185" iyy="0.860479" izz="0.891441" ixy="-0.123344" iyz="-0.00014" ixz="0.001526"/>
  </inertial>
  <visual>
    <origin xyz="-0.377 -0.000676 -1.243" rpy="0 0 0"/>
    <geometry>
      <mesh filename="meshes/link_4.stl" scale="0.001 0.001 0.001"/>
    </geometry>
  </visual>
  <collision>
    <origin xyz="-0.377 -0.000676 -1.243" rpy="0 0 0"/>
    <geometry>
      <mesh filename="meshes/link_4.stl" scale="0.001 0.001 0.001"/>
    </geometry>
  </collision>
</link>

<link name="link_5">
  <inertial>
    <origin xyz="0.08003843824392387 -0.024836643137220026 8.743162421964712e-05" rpy="0 0 0"/>
    <mass value="4.145062543835652"/>
    <inertia ixx="0.004992" iyy="0.023932" izz="0.024057" ixy="0.004073" iyz="-8e-06" ixz="3.5e-05"/>
  </inertial>
  <visual>
    <origin xyz="-0.883 -0.0525 -1.243" rpy="0 0 0"/>
    <geometry>
      <mesh filename="meshes/link_5.stl" scale="0.001 0.001 0.001"/>
    </geometry>
  </visual>
  <collision>
    <origin xyz="-0.883 -0.0525 -1.243" rpy="0 0 0"/>
    <geometry>
      <mesh filename="meshes/link_5.stl" scale="0.001 0.001 0.001"/>
    </geometry>
  </collision>
</link>

<link name="link_6">
  <inertial>
    <origin xyz="-0.013187035609442788 -1.7891235431793164e-09 -0.00010144891816454837" rpy="0 0 0"/>
    <mass value="0.7222246780605773"/>
    <inertia ixx="0.000572" iyy="0.000513" izz="0.000515" ixy="0.0" iyz="0.0" ixz="1e-06"/>
  </inertial>
  <visual>
    <origin xyz="-1.072629 -0.0 -1.243" rpy="0 0 0"/>
    <geometry>
      <mesh filename="meshes/link_6.stl" scale="0.001 0.001 0.001"/>
    </geometry>
  </visual>
  <collision>
    <origin xyz="-1.072629 -0.0 -1.243" rpy="0 0 0"/>
    <geometry>
      <mesh filename="meshes/link_6.stl" scale="0.001 0.001 0.001"/>
    </geometry>
  </collision>
</link>

<joint name="joint_1" type="revolute">
  <origin xyz="0.0 0.0 0.179" rpy="0 0 0"/>
  <parent link="base_link"/>
  <child link="link_1"/>
  <axis xyz="-0.0 -0.0 1.0"/>
  <limit lower="-2.967" upper="2.967" velocity="2.2689" effort="250"/>
</joint>

<joint name="joint_2" type="revolute">
  <origin xyz="0.16 -0.101 0.274" rpy="0 0 0"/>
  <parent link="link_1"/>
  <child link="link_2"/>
  <axis xyz="0.0 -1.0 -0.0"/>
  <limit lower="-1.571" upper="2.618" velocity="2.4435" effort="200"/>
</joint>

<joint name="joint_3" type="revolute">
  <origin xyz="0.0 -0.02 0.59" rpy="0 0 0"/>
  <parent link="link_2"/>
  <child link="link_3"/>
  <axis xyz="0.0 -1.0 -0.0"/>
  <limit lower="-1.745" upper="1.396" velocity="2.4435" effort="180"/>
</joint>

<joint name="joint_4" type="revolute">
  <origin xyz="0.217 0.121676 0.2" rpy="0 0 0"/>
  <parent link="link_3"/>
  <child link="link_4"/>
  <axis xyz="-1.0 -0.0 0.0"/>
  <limit lower="-2.705" upper="2.705" velocity="5.5851" effort="100"/>
</joint>

<joint name="joint_5" type="revolute">
  <origin xyz="0.506 0.051824 0.0" rpy="0 0 0"/>
  <parent link="link_4"/>
  <child link="link_5"/>
  <axis xyz="0.0 -1.0 -0.0"/>
  <limit lower="-2.356" upper="2.356" velocity="6.6323" effort="80"/>
</joint>

<joint name="joint_6" type="revolute">
  <origin xyz="0.189629 -0.0525 0.0" rpy="0 0 0"/>
  <parent link="link_5"/>
  <child link="link_6"/>
  <axis xyz="1.0 0.0 0.0"/>
  <limit lower="-3.491" upper="3.491" velocity="8.0285" effort="50"/>
</joint>

<link name="flange">
</link>

<link name="tool0">
</link>

<joint name="joint_6-flange" type="fixed">
  <origin xyz="0.0 0.0 0.0" rpy="0 1.57 0"/>
  <parent link="link_6"/>
  <child link="flange"/>
</joint>

<joint name="flange-tool0" type="fixed">
  <origin xyz="0.0 0.0 0.0" rpy="0 0 0"/>
  <parent link="flange"/>
  <child link="tool0"/>
</joint>

</robot>