<?xml version="1.0" ?>
<robot name="IRB5510-12_rev00_CAD">

<link name="base_link">
  <inertial>
    <origin xyz="-0.2198204163586881 0.00042151470984517657 0.30730920125871913" rpy="0 0 0"/>
    <mass value="546.7722107426896"/>
    <inertia ixx="27.709277" iyy="24.796335" izz="29.080443" ixy="0.039251" iyz="-0.014815" ixz="-3.497016"/>
  </inertial>
  <visual>
    <origin xyz="0 0 0" rpy="0 0 0"/>
    <geometry>
      <mesh filename="package://IRB5510-12_rev00_CAD_description/meshes/base_link.stl" scale="0.001 0.001 0.001"/>
    </geometry>
    <material name="silver"/>
  </visual>
  <collision>
    <origin xyz="0 0 0" rpy="0 0 0"/>
    <geometry>
      <mesh filename="package://IRB5510-12_rev00_CAD_description/meshes/base_link.stl" scale="0.001 0.001 0.001"/>
    </geometry>
  </collision>
</link>

<link name="IRB5510-12_rev00_LINK1_CAD_1">
  <inertial>
    <origin xyz="-0.002088148900103687 -0.0142436224415375 0.297387949872579" rpy="0 0 0"/>
    <mass value="760.5077067741645"/>
    <inertia ixx="32.796717" iyy="38.935759" izz="27.690645" ixy="0.107341" iyz="4.755505" ixz="0.176021"/>
  </inertial>
  <visual>
    <origin xyz="-0.0 -0.0 -0.484" rpy="0 0 0"/>
    <geometry>
      <mesh filename="package://IRB5510-12_rev00_CAD_description/meshes/IRB5510-12_rev00_LINK1_CAD_1.stl" scale="0.001 0.001 0.001"/>
    </geometry>
    <material name="silver"/>
  </visual>
  <collision>
    <origin xyz="-0.0 -0.0 -0.484" rpy="0 0 0"/>
    <geometry>
      <mesh filename="package://IRB5510-12_rev00_CAD_description/meshes/IRB5510-12_rev00_LINK1_CAD_1.stl" scale="0.001 0.001 0.001"/>
    </geometry>
  </collision>
</link>

<link name="IRB5510-12_rev00_LINK2_CAD_1">
  <inertial>
    <origin xyz="0.00012951666553344317 -0.09623909065982458 0.6070805314545756" rpy="0 0 0"/>
    <mass value="534.057436168823"/>
    <inertia ixx="82.304409" iyy="84.049941" izz="6.185354" ixy="0.051067" iyz="1.13366" ixz="0.042148"/>
  </inertial>
  <visual>
    <origin xyz="0.0 0.231 -0.92" rpy="0 0 0"/>
    <geometry>
      <mesh filename="package://IRB5510-12_rev00_CAD_description/meshes/IRB5510-12_rev00_LINK2_CAD_1.stl" scale="0.001 0.001 0.001"/>
    </geometry>
    <material name="silver"/>
  </visual>
  <collision>
    <origin xyz="0.0 0.231 -0.92" rpy="0 0 0"/>
    <geometry>
      <mesh filename="package://IRB5510-12_rev00_CAD_description/meshes/IRB5510-12_rev00_LINK2_CAD_1.stl" scale="0.001 0.001 0.001"/>
    </geometry>
  </collision>
</link>

<link name="IRB5510-12_rev00_LINK3_CAD_1">
  <inertial>
    <origin xyz="0.3438035099812337 0.1378290112414401 3.352144561930004e-08" rpy="0 0 0"/>
    <mass value="510.571285741552"/>
    <inertia ixx="4.896184" iyy="71.120767" izz="70.249143" ixy="-3.753696" iyz="0.0" ixz="9e-06"/>
  </inertial>
  <visual>
    <origin xyz="-0.0 0.217 -2.02" rpy="0 0 0"/>
    <geometry>
      <mesh filename="package://IRB5510-12_rev00_CAD_description/meshes/IRB5510-12_rev00_LINK3_CAD_1.stl" scale="0.001 0.001 0.001"/>
    </geometry>
    <material name="silver"/>
  </visual>
  <collision>
    <origin xyz="-0.0 0.217 -2.02" rpy="0 0 0"/>
    <geometry>
      <mesh filename="package://IRB5510-12_rev00_CAD_description/meshes/IRB5510-12_rev00_LINK3_CAD_1.stl" scale="0.001 0.001 0.001"/>
    </geometry>
  </collision>
</link>

<link name="IRB5510-12_rev00_LINK4_CAD_1">
  <inertial>
    <origin xyz="0.04504418824683665 0.015640363607786298 -5.6340825782541515e-08" rpy="0 0 0"/>
    <mass value="13.246564877496244"/>
    <inertia ixx="0.043539" iyy="0.036823" izz="0.029169" ixy="-0.006373" iyz="0.0" ixz="-0.0"/>
  </inertial>
  <visual>
    <origin xyz="-1.219 0.0 -2.02" rpy="0 0 0"/>
    <geometry>
      <mesh filename="package://IRB5510-12_rev00_CAD_description/meshes/IRB5510-12_rev00_LINK4_CAD_1.stl" scale="0.001 0.001 0.001"/>
    </geometry>
    <material name="silver"/>
  </visual>
  <collision>
    <origin xyz="-1.219 0.0 -2.02" rpy="0 0 0"/>
    <geometry>
      <mesh filename="package://IRB5510-12_rev00_CAD_description/meshes/IRB5510-12_rev00_LINK4_CAD_1.stl" scale="0.001 0.001 0.001"/>
    </geometry>
  </collision>
</link>

<link name="IRB5510-12_rev00_LINK5_CAD_1">
  <inertial>
    <origin xyz="0.059936040885649744 -0.022501914863573776 9.342077778029534e-08" rpy="0 0 0"/>
    <mass value="22.90378370207612"/>
    <inertia ixx="0.078073" iyy="0.096705" izz="0.075709" ixy="0.0" iyz="0.0" ixz="0.0"/>
  </inertial>
  <visual>
    <origin xyz="-1.293415 0.003441 -2.02" rpy="0 0 0"/>
    <geometry>
      <mesh filename="package://IRB5510-12_rev00_CAD_description/meshes/IRB5510-12_rev00_LINK5_CAD_1.stl" scale="0.001 0.001 0.001"/>
    </geometry>
    <material name="silver"/>
  </visual>
  <collision>
    <origin xyz="-1.293415 0.003441 -2.02" rpy="0 0 0"/>
    <geometry>
      <mesh filename="package://IRB5510-12_rev00_CAD_description/meshes/IRB5510-12_rev00_LINK5_CAD_1.stl" scale="0.001 0.001 0.001"/>
    </geometry>
  </collision>
</link>

<link name="IRB5510-12_rev00_LINK5B_CAD_1">
  <inertial>
    <origin xyz="0.02732309547874623 0.0150661145565937 2.519886863616705e-07" rpy="0 0 0"/>
    <mass value="11.027488801145376"/>
    <inertia ixx="0.031527" iyy="0.028228" izz="0.022716" ixy="0.005894" iyz="0.0" ixz="-0.0"/>
  </inertial>
  <visual>
    <origin xyz="-1.413287 0.003441 -2.02" rpy="0 0 0"/>
    <geometry>
      <mesh filename="package://IRB5510-12_rev00_CAD_description/meshes/IRB5510-12_rev00_LINK5B_CAD_1.stl" scale="0.001 0.001 0.001"/>
    </geometry>
    <material name="silver"/>
  </visual>
  <collision>
    <origin xyz="-1.413287 0.003441 -2.02" rpy="0 0 0"/>
    <geometry>
      <mesh filename="package://IRB5510-12_rev00_CAD_description/meshes/IRB5510-12_rev00_LINK5B_CAD_1.stl" scale="0.001 0.001 0.001"/>
    </geometry>
  </collision>
</link>

<link name="IRB5510-12_rev00_LINK6_CAD_1">
  <inertial>
    <origin xyz="-0.005525322762831575 -7.898034053255287e-07 -1.423777321374331e-06" rpy="0 0 0"/>
    <mass value="0.3574993425525093"/>
    <inertia ixx="0.001069" iyy="0.000527" izz="0.000548" ixy="-0.0" iyz="5e-06" ixz="-0.0"/>
  </inertial>
  <visual>
    <origin xyz="-1.5001 0.0 -2.02" rpy="0 0 0"/>
    <geometry>
      <mesh filename="package://IRB5510-12_rev00_CAD_description/meshes/IRB5510-12_rev00_LINK6_CAD_1.stl" scale="0.001 0.001 0.001"/>
    </geometry>
    <material name="silver"/>
  </visual>
  <collision>
    <origin xyz="-1.5001 0.0 -2.02" rpy="0 0 0"/>
    <geometry>
      <mesh filename="package://IRB5510-12_rev00_CAD_description/meshes/IRB5510-12_rev00_LINK6_CAD_1.stl" scale="0.001 0.001 0.001"/>
    </geometry>
  </collision>
</link>

<joint name="j1" type="continuous">
  <origin xyz="0.0 0.0 0.484" rpy="0 0 0"/>
  <parent link="base_link"/>
  <child link="IRB5510-12_rev00_LINK1_CAD_1"/>
  <axis xyz="0.0 0.0 -1.0"/>
</joint>

<joint name="j2" type="continuous">
  <origin xyz="-0.0 -0.231 0.436" rpy="0 0 0"/>
  <parent link="IRB5510-12_rev00_LINK1_CAD_1"/>
  <child link="IRB5510-12_rev00_LINK2_CAD_1"/>
  <axis xyz="0.0 1.0 0.0"/>
</joint>

<joint name="j3" type="continuous">
  <origin xyz="0.0 0.014 1.1" rpy="0 0 0"/>
  <parent link="IRB5510-12_rev00_LINK2_CAD_1"/>
  <child link="IRB5510-12_rev00_LINK3_CAD_1"/>
  <axis xyz="0.0 1.0 0.0"/>
</joint>

<joint name="j4" type="continuous">
  <origin xyz="1.219 0.217 0.0" rpy="0 0 0"/>
  <parent link="IRB5510-12_rev00_LINK3_CAD_1"/>
  <child link="IRB5510-12_rev00_LINK4_CAD_1"/>
  <axis xyz="1.0 0.0 0.0"/>
</joint>

<joint name="j5" type="continuous">
  <origin xyz="0.074415 -0.003441 0.0" rpy="0 0 0"/>
  <parent link="IRB5510-12_rev00_LINK4_CAD_1"/>
  <child link="IRB5510-12_rev00_LINK5_CAD_1"/>
  <axis xyz="0.819152 -0.573576 0.0"/>
</joint>

<joint name="j6" type="continuous">
  <origin xyz="0.119872 0.0 0.0" rpy="0 0 0"/>
  <parent link="IRB5510-12_rev00_LINK5_CAD_1"/>
  <child link="IRB5510-12_rev00_LINK5B_CAD_1"/>
  <axis xyz="0.819152 0.573576 0.0"/>
</joint>

<joint name="j6b" type="revolute">
  <origin xyz="0.086813 0.003441 0.0" rpy="0 0 0"/>
  <parent link="IRB5510-12_rev00_LINK5B_CAD_1"/>
  <child link="IRB5510-12_rev00_LINK6_CAD_1"/>
  <axis xyz="-1.0 0.0 -0.0"/>
  <limit upper="0.0" lower="0.0" effort="100" velocity="100"/>
</joint>

</robot>
