<?xml version="1.0" ?>
<robot name="IRB920_6kg-650-180-STD_OmniCore_rev00_Assembly" xmlns:xacro="http://www.ros.org/wiki/xacro">

<xacro:include filename="$(find IRB920_6kg-650-180-STD_OmniCore_rev00_Assembly_description)/urdf/materials.xacro" />
<xacro:include filename="$(find IRB920_6kg-650-180-STD_OmniCore_rev00_Assembly_description)/urdf/IRB920_6kg-650-180-STD_OmniCore_rev00_Assembly.trans" />
<xacro:include filename="$(find IRB920_6kg-650-180-STD_OmniCore_rev00_Assembly_description)/urdf/IRB920_6kg-650-180-STD_OmniCore_rev00_Assembly.gazebo" />
<link name="base_link">
  <inertial>
    <origin xyz="-0.02500708496170239 4.832861134834105e-06 0.0942820642453871" rpy="0 0 0"/>
    <mass value="41.12591553669811"/>
    <inertia ixx="0.182723" iyy="0.263418" izz="0.209732" ixy="5.3e-05" iyz="2e-06" ixz="0.005906"/>
  </inertial>
  <visual>
    <origin xyz="0 0 0" rpy="0 0 0"/>
    <geometry>
      <mesh filename="package://IRB920_6kg-650-180-STD_OmniCore_rev00_Assembly_description/meshes/base_link.stl" scale="0.001 0.001 0.001"/>
    </geometry>
    <material name="silver"/>
  </visual>
  <collision>
    <origin xyz="0 0 0" rpy="0 0 0"/>
    <geometry>
      <mesh filename="package://IRB920_6kg-650-180-STD_OmniCore_rev00_Assembly_description/meshes/base_link.stl" scale="0.001 0.001 0.001"/>
    </geometry>
  </collision>
</link>

<link name="IRB920_6kg-650-180-STD_OmniCore_rev00_LINK1_CAD.STEP_1">
  <inertial>
    <origin xyz="0.17258528277481563 4.324208514675313e-06 0.04683297673687792" rpy="0 0 0"/>
    <mass value="40.4824375073"/>
    <inertia ixx="0.086331" iyy="0.913744" izz="0.966259" ixy="2.3e-05" iyz="1e-05" ixz="-0.029501"/>
  </inertial>
  <visual>
    <origin xyz="0.00025 -2e-06 -0.1914" rpy="0 0 0"/>
    <geometry>
      <mesh filename="package://IRB920_6kg-650-180-STD_OmniCore_rev00_Assembly_description/meshes/IRB920_6kg-650-180-STD_OmniCore_rev00_LINK1_CAD.STEP_1.stl" scale="0.001 0.001 0.001"/>
    </geometry>
    <material name="silver"/>
  </visual>
  <collision>
    <origin xyz="0.00025 -2e-06 -0.1914" rpy="0 0 0"/>
    <geometry>
      <mesh filename="package://IRB920_6kg-650-180-STD_OmniCore_rev00_Assembly_description/meshes/IRB920_6kg-650-180-STD_OmniCore_rev00_LINK1_CAD.STEP_1.stl" scale="0.001 0.001 0.001"/>
    </geometry>
  </collision>
</link>

<link name="IRB920_6kg-650-180-STD_OmniCore_rev00_LINK2_CAD.STEP_1">
  <inertial>
    <origin xyz="0.09786963144856903 2.835673922048506e-06 0.08518137848367535" rpy="0 0 0"/>
    <mass value="75.77408460831636"/>
    <inertia ixx="0.309324" iyy="1.206998" izz="1.132456" ixy="1.3e-05" iyz="1.8e-05" ixz="0.072377"/>
  </inertial>
  <visual>
    <origin xyz="-0.391498 -0.0 -0.2785" rpy="0 0 0"/>
    <geometry>
      <mesh filename="package://IRB920_6kg-650-180-STD_OmniCore_rev00_Assembly_description/meshes/IRB920_6kg-650-180-STD_OmniCore_rev00_LINK2_CAD.STEP_1.stl" scale="0.001 0.001 0.001"/>
    </geometry>
    <material name="silver"/>
  </visual>
  <collision>
    <origin xyz="-0.391498 -0.0 -0.2785" rpy="0 0 0"/>
    <geometry>
      <mesh filename="package://IRB920_6kg-650-180-STD_OmniCore_rev00_Assembly_description/meshes/IRB920_6kg-650-180-STD_OmniCore_rev00_LINK2_CAD.STEP_1.stl" scale="0.001 0.001 0.001"/>
    </geometry>
  </collision>
</link>

<link name="IRB920_6kg-650-180-STD_OmniCore_rev00_LINK3_CAD.STEP_1">
  <inertial>
    <origin xyz="-7.554934788145395e-05 -7.45327058237817e-05 -0.17600468195116148" rpy="0 0 0"/>
    <mass value="0.6594614836495672"/>
    <inertia ixx="0.011651" iyy="0.011651" izz="7.7e-05" ixy="1e-06" iyz="-0.0" ixz="1e-06"/>
  </inertial>
  <visual>
    <origin xyz="-0.65 0.0 -0.5835" rpy="0 0 0"/>
    <geometry>
      <mesh filename="package://IRB920_6kg-650-180-STD_OmniCore_rev00_Assembly_description/meshes/IRB920_6kg-650-180-STD_OmniCore_rev00_LINK3_CAD.STEP_1.stl" scale="0.001 0.001 0.001"/>
    </geometry>
    <material name="silver"/>
  </visual>
  <collision>
    <origin xyz="-0.65 0.0 -0.5835" rpy="0 0 0"/>
    <geometry>
      <mesh filename="package://IRB920_6kg-650-180-STD_OmniCore_rev00_Assembly_description/meshes/IRB920_6kg-650-180-STD_OmniCore_rev00_LINK3_CAD.STEP_1.stl" scale="0.001 0.001 0.001"/>
    </geometry>
  </collision>
</link>

<joint name="Revolute 1" type="continuous">
  <origin xyz="-0.00025 2e-06 0.1914" rpy="0 0 0"/>
  <parent link="base_link"/>
  <child link="IRB920_6kg-650-180-STD_OmniCore_rev00_LINK1_CAD.STEP_1"/>
  <axis xyz="0.0 0.0 1.0"/>
</joint>

<joint name="Revolute 2" type="continuous">
  <origin xyz="0.391748 -2e-06 0.0871" rpy="0 0 0"/>
  <parent link="IRB920_6kg-650-180-STD_OmniCore_rev00_LINK1_CAD.STEP_1"/>
  <child link="IRB920_6kg-650-180-STD_OmniCore_rev00_LINK2_CAD.STEP_1"/>
  <axis xyz="0.0 0.0 1.0"/>
</joint>

<joint name="Slider 3" type="prismatic">
  <origin xyz="0.258502 -0.0 0.305" rpy="0 0 0"/>
  <parent link="IRB920_6kg-650-180-STD_OmniCore_rev00_LINK2_CAD.STEP_1"/>
  <child link="IRB920_6kg-650-180-STD_OmniCore_rev00_LINK3_CAD.STEP_1"/>
  <axis xyz="0.0 0.0 1.0"/>
  <limit upper="0.0" lower="-0.1" effort="100" velocity="100"/>
</joint>

</robot>
