<?xml version="1.0" ?>
<robot name="CRB15000_10kg_152">

<link name="base_link">
  <inertial>
    <origin xyz="-0.0011656606666003504 -0.00011127786600189595 0.0985691713362607" rpy="0 0 0"/>
    <mass value="43.321834194728716"/>
    <inertia ixx="0.254824" iyy="0.26074" izz="0.191484" ixy="-0.000567" iyz="-0.000372" ixz="-0.003894"/>
  </inertial>
  <visual>
    <origin xyz="0 0 0" rpy="0 0 0"/>
    <geometry>
      <mesh filename="meshes/base_link.stl" scale="0.001 0.001 0.001"/>
    </geometry>
  </visual>
  <collision>
    <origin xyz="0 0 0" rpy="0 0 0"/>
    <geometry>
      <mesh filename="meshes/base_link.stl" scale="0.001 0.001 0.001"/>
    </geometry>
  </collision>
</link>

<link name="link_1">
  <inertial>
    <origin xyz="0.08775396256753097 0.0028936166670680574 0.13782832227067018" rpy="0 0 0"/>
    <mass value="62.519803241843114"/>
    <inertia ixx="0.432284" iyy="0.648762" izz="0.530762" ixy="-0.011248" iyz="-0.008525" ixz="-0.212957"/>
  </inertial>
  <visual>
    <origin xyz="0.0 -0.0 -0.218" rpy="0 0 0"/>
    <geometry>
      <mesh filename="meshes/link_1_1.stl" scale="0.001 0.001 0.001"/>
    </geometry>
  </visual>
  <collision>
    <origin xyz="0.0 -0.0 -0.218" rpy="0 0 0"/>
    <geometry>
      <mesh filename="meshes/link_1_1.stl" scale="0.001 0.001 0.001"/>
    </geometry>
  </collision>
</link>

<link name="link_2">
  <inertial>
    <origin xyz="2.8584459371705506e-07 -0.0543214282069112 0.31993968763231195" rpy="0 0 0"/>
    <mass value="70.93354798589783"/>
    <inertia ixx="4.564667" iyy="4.624738" izz="0.149368" ixy="0.0" iyz="-0.067787" ixz="1e-06"/>
  </inertial>
  <visual>
    <origin xyz="-0.15 0.0 -0.400014" rpy="0 0 0"/>
    <geometry>
      <mesh filename="meshes/link_2_1.stl" scale="0.001 0.001 0.001"/>
    </geometry>
  </visual>
  <collision>
    <origin xyz="-0.15 0.0 -0.400014" rpy="0 0 0"/>
    <geometry>
      <mesh filename="meshes/link_2_1.stl" scale="0.001 0.001 0.001"/>
    </geometry>
  </collision>
</link>

<link name="link_3">
  <inertial>
    <origin xyz="0.012899148223606716 0.09273704088636267 0.024906939924447702" rpy="0 0 0"/>
    <mass value="26.381731962599385"/>
    <inertia ixx="0.135785" iyy="0.109627" izz="0.102204" ixy="0.002633" iyz="0.005085" ixz="-0.02496"/>
  </inertial>
  <visual>
    <origin xyz="-0.15 0.0 -1.107" rpy="0 0 0"/>
    <geometry>
      <mesh filename="meshes/link_3_1.stl" scale="0.001 0.001 0.001"/>
    </geometry>
  </visual>
  <collision>
    <origin xyz="-0.15 0.0 -1.107" rpy="0 0 0"/>
    <geometry>
      <mesh filename="meshes/link_3_1.stl" scale="0.001 0.001 0.001"/>
    </geometry>
  </collision>
</link>

<link name="link_4">
  <inertial>
    <origin xyz="0.24242614990615624 0.06277136599398273 6.636508358415227e-07" rpy="0 0 0"/>
    <mass value="32.073735291819936"/>
    <inertia ixx="0.109076" iyy="0.893804" izz="0.956571" ixy="-0.193211" iyz="2e-06" ixz="1.3e-05"/>
  </inertial>
  <visual>
    <origin xyz="-0.150 0.0 -1.217" rpy="0 0 0"/>
    <geometry>
      <mesh filename="meshes/link_4_1.stl" scale="0.001 0.001 0.001"/>
    </geometry>
  </visual>
  <collision>
    <origin xyz="-0.150 0.0 -1.217" rpy="0 0 0"/>
    <geometry>
      <mesh filename="meshes/link_4_1.stl" scale="0.001 0.001 0.001"/>
    </geometry>
  </collision>
</link>

<link name="link_5">
  <inertial>
    <origin xyz="-0.01459775541258479 -0.07956678438355705 0.04275435393134619" rpy="0 0 0"/>
    <mass value="23.637549891653943"/>
    <inertia ixx="0.089959" iyy="0.106455" izz="0.085161" ixy="0.001414" iyz="-0.004125" ixz="0.012973"/>
  </inertial>
  <visual>
    <origin xyz="-0.786883 -0.0 -1.217" rpy="0 0 0"/>
    <geometry>
      <mesh filename="meshes/link_5_1.stl" scale="0.001 0.001 0.001"/>
    </geometry>
  </visual>
  <collision>
    <origin xyz="-0.786883 -0.0 -1.217" rpy="0 0 0"/>
    <geometry>
      <mesh filename="meshes/link_5_1.stl" scale="0.001 0.001 0.001"/>
    </geometry>
  </collision>
</link>

<link name="link_6">
  <inertial>
    <origin xyz="0.013150737690741043 0.00023981661745750953 -0.00034190626182106776" rpy="0 0 0"/>
    <mass value="1.1500367477208804"/>
    <inertia ixx="0.001012" iyy="0.000597" izz="0.0006" ixy="-1e-06" iyz="-5e-06" ixz="1e-06"/>
  </inertial>
  <visual>
    <origin xyz="-0.890 -0.0 -1.297" rpy="0 0 0"/>
    <geometry>
      <mesh filename="meshes/link_6_1.stl" scale="0.001 0.001 0.001"/>
    </geometry>
  </visual>
  <collision>
    <origin xyz="-0.890 -0.0 -1.297" rpy="0 0 0"/>
    <geometry>
      <mesh filename="meshes/link_6_1.stl" scale="0.001 0.001 0.001"/>
    </geometry>
  </collision>
</link>

<joint name="joint_1" type="revolute">
  <origin xyz="0.0 0.0 0.218" rpy="0 0 0"/>
  <parent link="base_link"/>
  <child link="link_1"/>
  <axis xyz="0.0 0.0 1.0"/>
  <limit upper="4.712" lower="-4.712" effort="450" velocity="2.094"/>
</joint>

<joint name="joint_2" type="revolute">
<!-- 0.15 is good, probably should be 0, needs to be up to 0.400 so OK -->
  <origin xyz="0.15 0.0 0.182" rpy="0 0 0"/>
  <parent link="link_1"/>
  <child link="link_2"/>
  <axis xyz="0.0 1.0 0.0"/>
  <limit upper="3.14159" lower="-3.14159" effort="400" velocity="2.094"/>
</joint>

<joint name="joint_3" type="revolute">
  <!-- 0 good, should be 0, needs to be up to 1.107 -->
  <origin xyz="0.0 0.0 0.707" rpy="0 0 0"/>
  <parent link="link_2"/>
  <child link="link_3"/>
  <axis xyz="0.0 1.0 0.0"/>
  <limit upper="3.927" lower="-1.483" effort="160" velocity="2.181"/>
</joint>

<joint name="joint_4" type="revolute">
  <!-- going to trust, should be 0, correct -->
  <!-- <origin xyz="0.096 0.0 0.11" rpy="0 0 0"/> -->
  <origin xyz="0.0 0.0 0.110" rpy="0 0 0"/>
  <parent link="link_3"/>
  <child link="link_4"/>
  <axis xyz="1.0 0.0 0.0"/>
  <limit upper="3.14159" lower="-3.14159" effort="60" velocity="3.491"/>
</joint>

<joint name="joint_5" type="revolute">
  <!-- <origin xyz="0.540883 0.0755 0.0" rpy="0 0 0"/> -->
  <!-- 787-150, 0, 0 -->
  <origin xyz="0.637 0.0 0.0" rpy="0 0 0"/>

  <parent link="link_4"/>
  <child link="link_5"/>
  <axis xyz="0.0 1.0 0.0"/>
  <limit upper="3.14159" lower="-3.14159" effort="60" velocity="3.491"/>
</joint>

<joint name="joint_6" type="revolute">
  <!-- <origin xyz="0.068117 -0.0755 0.08" rpy="0 0 0"/> -->
  <!-- 888-787, 0, 1297-1217 -->
  <origin xyz="0.101 0.0 0.080" rpy="0 0 0"/>
  <parent link="link_5"/>
  <child link="link_6"/>
  <axis xyz="1.0 0.0 0.0"/>
  <limit upper="4.712" lower="-4.712" effort="60" velocity="3.491"/>
</joint>

<link name="flange">
  <inertial>
    <origin xyz="0 0 0" rpy="0 0 0"/>
    <mass value="0.1"/>
    <inertia ixx="0.0001" iyy="0.0001" izz="0.0001" ixy="0" iyz="0" ixz="0"/>
  </inertial>
</link>

<link name="tool0">
  <inertial>
    <origin xyz="0 0 0" rpy="0 0 0"/>
    <mass value="0.01"/>
    <inertia ixx="0.00001" iyy="0.00001" izz="0.00001" ixy="0" iyz="0" ixz="0"/>
  </inertial>
</link>

<joint name="joint_flange" type="fixed">
  <origin xyz="0 0 0" rpy="0 1.57 0"/>
  <parent link="link_6"/>
  <child link="flange"/>
</joint>

<joint name="joint_tool0" type="fixed">
  <origin xyz="0 0 0" rpy="0 0 0"/>
  <parent link="flange"/>
  <child link="tool0"/>
</joint>

</robot>