<?xml version="1.0" ?>
<robot name="IRB910INV_350">

<link name="base_link">
  <inertial>
    <origin xyz="-0.03428217335737813 -2.4667588020476706e-07 0.08971070325608167" rpy="0 0 0"/>
    <mass value="47.926347738289834"/>
    <inertia ixx="0.305149" iyy="0.354553" izz="0.217137" ixy="-4e-06" iyz="9.8e-05" ixz="0.004008"/>
  </inertial>
  <visual>
    <origin xyz="0 0 0" rpy="0 0 0"/>
    <geometry>
      <mesh filename="meshes/base_link.stl" scale="0.001 0.001 0.001"/>
    </geometry>
  </visual>
  <collision>
    <origin xyz="0 0 0" rpy="0 0 0"/>
    <geometry>
      <mesh filename="meshes/base_link.stl" scale="0.001 0.001 0.001"/>
    </geometry>
  </collision>
</link>

<link name="link_1">
  <inertial>
    <origin xyz="0.11275513176109886 1.7513838112814044e-05 -0.0951509538380555" rpy="0 0 0"/>
    <mass value="33.86232074637399"/>
    <inertia ixx="0.142639" iyy="0.278472" izz="0.206182" ixy="2.3e-05" iyz="-2.8e-05" ixz="0.067431"/>
  </inertial>
  <visual>
    <origin xyz="-0.0 -4e-06 0.0225" rpy="0 0 0"/>
    <geometry>
      <mesh filename="meshes/link_1.stl" scale="0.001 0.001 0.001"/>
    </geometry>
  </visual>
  <collision>
    <origin xyz="-0.0 -4e-06 0.0225" rpy="0 0 0"/>
    <geometry>
      <mesh filename="meshes/link_1.stl" scale="0.001 0.001 0.001"/>
    </geometry>
  </collision>
</link>

<link name="link_2">
  <inertial>
    <origin xyz="-0.07748210763311644 2.4149022072988045e-05 -0.08074925775211947" rpy="0 0 0"/>
    <mass value="36.19533232147432"/>
    <inertia ixx="0.105427" iyy="0.262885" izz="0.242365" ixy="-1e-06" iyz="-3.7e-05" ixz="-0.014601"/>
  </inertial>
  <visual>
    <origin xyz="-0.174731 0.0 0.228" rpy="0 0 0"/>
    <geometry>
      <mesh filename="meshes/link_2.stl" scale="0.001 0.001 0.001"/>
    </geometry>
  </visual>
  <collision>
    <origin xyz="-0.174731 0.0 0.228" rpy="0 0 0"/>
    <geometry>
      <mesh filename="meshes/link_2.stl" scale="0.001 0.001 0.001"/>
    </geometry>
  </collision>
</link>

<link name="link_3">
  <inertial>
    <origin xyz="2.217347784446274e-06 -6.636237422544021e-06 -0.13387670086396194" rpy="0 0 0"/>
    <mass value="0.7548467951787753"/>
    <inertia ixx="0.011663" iyy="0.011663" izz="9.1e-05" ixy="0.0" iyz="-0.0" ixz="0.0"/>
  </inertial>
  <visual>
    <origin xyz="0.0 -7e-06 0.158" rpy="0 0 0"/>
    <geometry>
      <mesh filename="meshes/link_3.stl" scale="0.001 0.001 0.001"/>
    </geometry>
  </visual>
  <collision>
    <origin xyz="0.0 -7e-06 0.158" rpy="0 0 0"/>
    <geometry>
      <mesh filename="meshes/link_3.stl" scale="0.001 0.001 0.001"/>
    </geometry>
  </collision>
</link>

<joint name="joint_1" type="revolute">
  <origin xyz="0.0 4e-06 -0.0225" rpy="0 0 0"/>
  <parent link="base_link"/>
  <child link="link_1"/>
  <axis xyz="0.0 0.0 -1.0"/>
  <limit lower="-2.61799" upper="2.61799" effort="0.0" velocity="0.0"/>
</joint>

<joint name="joint_2" type="revolute">
  <origin xyz="0.174731 -4e-06 -0.2055" rpy="0 0 0"/>
  <parent link="link_1"/>
  <child link="link_2"/>
  <axis xyz="0.0 0.0 -1.0"/>
  <limit lower="-2.53073" upper="2.53073" effort="0.0" velocity="0.0"/>
</joint>

<joint name="joint_3" type="prismatic">
  <origin xyz="-0.174731 7e-06 0.07" rpy="0 0 0"/>
  <parent link="link_2"/>
  <child link="link_3"/>
  <axis xyz="0.0 0.0 1.0"/>
  <limit upper="0.145" lower="0.0" effort="100" velocity="100"/>
</joint>

<transmission name="joint_1_tran">
  <type>transmission_interface/SimpleTransmission</type>
  <joint name="joint_1">
    <hardwareInterface>hardware_interface/EffortJointInterface</hardwareInterface>
  </joint>
  <actuator name="joint_1_actr">
    <hardwareInterface>hardware_interface/EffortJointInterface</hardwareInterface>
    <mechanicalReduction>1</mechanicalReduction>
  </actuator>
</transmission>

<transmission name="joint_2_tran">
  <type>transmission_interface/SimpleTransmission</type>
  <joint name="joint_2">
    <hardwareInterface>hardware_interface/EffortJointInterface</hardwareInterface>
  </joint>
  <actuator name="joint_2_actr">
    <hardwareInterface>hardware_interface/EffortJointInterface</hardwareInterface>
    <mechanicalReduction>1</mechanicalReduction>
  </actuator>
</transmission>

<transmission name="joint_3_tran">
  <type>transmission_interface/SimpleTransmission</type>
  <joint name="joint_3">
    <hardwareInterface>hardware_interface/EffortJointInterface</hardwareInterface>
  </joint>
  <actuator name="joint_3_actr">
    <hardwareInterface>hardware_interface/EffortJointInterface</hardwareInterface>
    <mechanicalReduction>1</mechanicalReduction>
  </actuator>
</transmission>

<joint name="joint_4" type="revolute">
  <origin xyz="0 0 0" rpy="0 0 0"/>
  <parent link="link_3"/>
  <child link="flange"/>
  <axis xyz="0.0 0.0 1.0"/>
  <limit lower="-6.98132" upper="6.98132" effort="0.0" velocity="0.0"/>
</joint>

<link name="flange">
  <inertial>
    <origin xyz="0 0 0" rpy="0 0 0"/>
    <mass value="0.1"/>
    <inertia ixx="0.0001" iyy="0.0001" izz="0.0001" ixy="0" iyz="0" ixz="0"/>
  </inertial>
</link>

<link name="tool0">
  <inertial>
    <origin xyz="0 0 0" rpy="0 0 0"/>
    <mass value="0.01"/>
    <inertia ixx="0.00001" iyy="0.00001" izz="0.00001" ixy="0" iyz="0" ixz="0"/>
  </inertial>
</link>

<joint name="joint_tool0" type="fixed">
  <origin xyz="0 0 0" rpy="0 0 0"/>
  <parent link="flange"/>
  <child link="tool0"/>
</joint>

</robot>