<?xml version="1.0" ?>
<robot name="CRB15000_5kg_950">

  <link name="base_link">
    <inertial>
      <origin xyz="-0.0012014538056427894 -0.0001751781553540673 0.08621477256851826" rpy="0 0 0"/>
      <mass value="27.481465640207425"/>
      <inertia ixx="0.120116" iyy="0.125077" izz="0.088047" ixy="-0.000503" iyz="-0.000312" ixz="-0.002172"/>
    </inertial>
    <visual>
      <origin xyz="0 0 0" rpy="0 0 0"/>
      <geometry>
        <mesh filename="meshes/base_link.stl" scale="0.001 0.001 0.001"/>
      </geometry>
    </visual>
    <collision>
      <origin xyz="0 0 0" rpy="0 0 0"/>
      <geometry>
        <mesh filename="meshes/base_link.stl" scale="0.001 0.001 0.001"/>
      </geometry>
    </collision>
    </link>

  <link name="link_1">
    <inertial>
      <origin xyz="-7.746834366601395e-08 0.010362421131137462 0.06952957358252931" rpy="0 0 0"/>
      <mass value="21.72390566115484"/>
      <inertia ixx="0.090397" iyy="0.050984" izz="0.085916" ixy="-0.0" iyz="-0.001544" ixz="-0.0"/>
    </inertial>
    <visual>
      <origin xyz="-0.0 -0.0 -0.1885" rpy="0 0 0"/>
      <geometry>
        <mesh filename="meshes/link_1.stl" scale="0.001 0.001 0.001"/>
      </geometry>
    </visual>
    <collision>
      <origin xyz="-0.0 -0.0 -0.1885" rpy="0 0 0"/>
      <geometry>
        <mesh filename="meshes/link_1.stl" scale="0.001 0.001 0.001"/>
      </geometry>
    </collision>
    </link>

  <link name="link_2">
    <inertial>
      <origin xyz="2.1392455886037183e-07 -0.05000931254700587 0.22199307110548416" rpy="0 0 0"/>
      <mass value="33.66814621553652"/>
      <inertia ixx="1.024636" iyy="1.04625" izz="0.052503" ixy="0.0" iyz="-8e-06" ixz="-0.0"/>
    </inertial>
    <visual>
      <origin xyz="0.0 0.085 -0.265" rpy="0 0 0"/>
      <geometry>
        <mesh filename="meshes/link_2.stl" scale="0.001 0.001 0.001"/>
      </geometry>
    </visual>
    <collision>
      <origin xyz="0.0 0.085 -0.265" rpy="0 0 0"/>
      <geometry>
        <mesh filename="meshes/link_2.stl" scale="0.001 0.001 0.001"/>
      </geometry>
    </collision>
    </link>

  <link name="link_3">
    <inertial>
      <origin xyz="0.012812810727324556 0.09441702109200067 0.024740268053319525" rpy="0 0 0"/>
      <mass value="26.559534737331685"/>
      <inertia ixx="0.137869" iyy="0.110083" izz="0.10421" ixy="0.002864" iyz="0.005532" ixz="-0.025016"/>
    </inertial>
    <visual>
      <origin xyz="-0.0 0.086 -0.709" rpy="0 0 0"/>
      <geometry>
        <mesh filename="meshes/link_3.stl" scale="0.001 0.001 0.001"/>
      </geometry>
    </visual>
    <collision>
      <origin xyz="-0.0 0.086 -0.709" rpy="0 0 0"/>
      <geometry>
        <mesh filename="meshes/link_3.stl" scale="0.001 0.001 0.001"/>
      </geometry>
    </collision>
    </link>

  <link name="link_4">
    <inertial>
      <origin xyz="0.16055875884974877 0.04197687995947815 -1.9470952039579714e-07" rpy="0 0 0"/>
      <mass value="21.811589078670252"/>
      <inertia ixx="0.069214" iyy="0.267493" izz="0.305648" ixy="-0.084359" iyz="0.0" ixz="1e-06"/>
    </inertial>
    <visual>
      <origin xyz="-0.096 0.0 -0.819" rpy="0 0 0"/>
      <geometry>
        <mesh filename="meshes/link_4.stl" scale="0.001 0.001 0.001"/>
      </geometry>
    </visual>
    <collision>
      <origin xyz="-0.096 0.0 -0.819" rpy="0 0 0"/>
      <geometry>
        <mesh filename="meshes/link_4.stl" scale="0.001 0.001 0.001"/>
      </geometry>
    </collision>
    </link>

  <link name="link_5">
    <inertial>
      <origin xyz="-0.014715042524463817 -0.07856500607442374 0.0427552269826047" rpy="0 0 0"/>
      <mass value="23.63690573076678"/>
      <inertia ixx="0.089956" iyy="0.106456" izz="0.08516" ixy="0.001414" iyz="-0.004124" ixz="0.012972"/>
    </inertial>
    <visual>
      <origin xyz="-0.47 -0.0745 -0.819" rpy="0 0 0"/>
      <geometry>
        <mesh filename="meshes/link_5.stl" scale="0.001 0.001 0.001"/>
      </geometry>
    </visual>
    <collision>
      <origin xyz="-0.47 -0.0745 -0.819" rpy="0 0 0"/>
      <geometry>
        <mesh filename="meshes/link_5.stl" scale="0.001 0.001 0.001"/>
      </geometry>
    </collision>
    </link>

  <link name="link_6">
    <inertial>
      <origin xyz="0.013150710928741538 0.00023981661746452662 -0.0003419398620416736" rpy="0 0 0"/>
      <mass value="1.1500367477202385"/>
      <inertia ixx="0.001012" iyy="0.000597" izz="0.000601" ixy="-1e-06" iyz="-5e-06" ixz="1e-06"/>
    </inertial>
    <visual>
      <origin xyz="-0.538 -0.0 -0.899" rpy="0 0 0"/>
      <geometry>
        <mesh filename="meshes/link_6.stl" scale="0.001 0.001 0.001"/>
      </geometry>
    </visual>
    <collision>
      <origin xyz="-0.538 -0.0 -0.899" rpy="0 0 0"/>
      <geometry>
        <mesh filename="meshes/link_6.stl" scale="0.001 0.001 0.001"/>
      </geometry>
    </collision>
    </link>

  <link name="flange">
    <inertial>
      <origin xyz="0 0 0" rpy="0 0 0"/>
      <mass value="0.1"/>
      <inertia ixx="0.0001" iyy="0.0001" izz="0.0001" ixy="0" iyz="0" ixz="0"/>
    </inertial>
  </link>

  <link name="tool0">
    <inertial>
      <origin xyz="0 0 0" rpy="0 0 0"/>
      <mass value="0.01"/>
      <inertia ixx="0.00001" iyy="0.00001" izz="0.00001" ixy="0" iyz="0" ixz="0"/>
    </inertial>
  </link>

  <joint name="joint_1" type="revolute">
    <origin xyz="0.0 0.0 0.1885" rpy="0 0 0"/>
    <parent link="base_link"/>
    <child link="link_1"/>
    <axis xyz="0.0 0.0 -1.0"/>
    <limit lower="-3.14159" upper="3.14159" effort="175.44" velocity="2.181"/>
    </joint>

  <joint name="joint_2" type="revolute">
    <origin xyz="-0.0 -0.085 0.0765" rpy="0 0 0"/>
    <parent link="link_1"/>
    <child link="link_2"/>
    <axis xyz="0.0 -1.0 0.0"/>
    <limit lower="-3.14159" upper="3.14159" effort="175.44" velocity="2.181"/>
    </joint>

  <joint name="joint_3" type="revolute">
    <origin xyz="0.0 -0.001 0.444" rpy="0 0 0"/>
    <parent link="link_2"/>
    <child link="link_3"/>
    <axis xyz="0.0 -1.0 0.0"/>
    <limit lower="-3.92699" upper="0.95993" effort="90.6" velocity="2.444"/>
    </joint>

  <joint name="joint_4" type="revolute">
    <origin xyz="0.096 0.086 0.11" rpy="0 0 0"/>
    <parent link="link_3"/>
    <child link="link_4"/>
    <axis xyz="1.0 0.0 0.0"/>
    <limit lower="-3.14159" upper="3.14159" effort="18.72" velocity="3.491"/>
    </joint>

  <joint name="joint_5" type="revolute">
    <origin xyz="0.374 0.0745 0.0" rpy="0 0 0"/>
    <parent link="link_4"/>
    <child link="link_5"/>
    <axis xyz="0.0 -1.0 0.0"/>
    <limit lower="-3.14159" upper="3.14159" effort="21.44" velocity="3.491"/>
    </joint>

  <joint name="joint_6" type="revolute">
    <origin xyz="0.068 -0.0745 0.08" rpy="0 0 0"/>
    <parent link="link_5"/>
    <child link="link_6"/>
    <axis xyz="1.0 0.0 0.0"/>
    <limit lower="-4.71239" upper="4.71239" effort="9.2" velocity="3.491"/>
    </joint>

  <joint name="joint_flange" type="fixed">
    <origin xyz="0 0 0" rpy="0 1.57 0"/>
    <parent link="link_6"/>
    <child link="flange"/>
  </joint>

  <joint name="joint_tool0" type="fixed">
    <origin xyz="0 0 0" rpy="0 0 0"/>
    <parent link="flange"/>
    <child link="tool0"/>
  </joint>

</robot>