<?xml version="1.0" ?>
<robot name="IRB14050_SAYuMi_-_rev00">

<link name="base_link">
  <inertial>
    <origin xyz="0.0067341529602538705 -4.242075529018596e-06 0.09331995585045105" rpy="0 0 0"/>
    <mass value="32.22380951244625"/>
    <inertia ixx="0.151725" iyy="0.164755" izz="0.108527" ixy="2.1e-05" iyz="-4e-06" ixz="0.00565"/>
  </inertial>
  <visual>
    <origin xyz="0 0 0" rpy="0 0 0"/>
    <geometry>
      <mesh filename="package://IRB14050_SAYuMi_-_rev00_description/meshes/base_link.stl" scale="0.001 0.001 0.001"/>
    </geometry>
    <material name="silver"/>
  </visual>
  <collision>
    <origin xyz="0 0 0" rpy="0 0 0"/>
    <geometry>
      <mesh filename="package://IRB14050_SAYuMi_-_rev00_description/meshes/base_link.stl" scale="0.001 0.001 0.001"/>
    </geometry>
  </collision>
</link>

<link name="Link1_R_1">
  <inertial>
    <origin xyz="-0.010302908951592258 0.02260577276044838 0.08311471108287838" rpy="0 0 0"/>
    <mass value="7.562885567589252"/>
    <inertia ixx="0.024135" iyy="0.023842" izz="0.013038" ixy="0.001983" iyz="-0.00674" ixz="0.004166"/>
  </inertial>
  <visual>
    <origin xyz="-0.0 0.0 -0.173832" rpy="0 0 0"/>
    <geometry>
      <mesh filename="package://IRB14050_SAYuMi_-_rev00_description/meshes/Link1_R_1.stl" scale="0.001 0.001 0.001"/>
    </geometry>
    <material name="silver"/>
  </visual>
  <collision>
    <origin xyz="-0.0 0.0 -0.173832" rpy="0 0 0"/>
    <geometry>
      <mesh filename="package://IRB14050_SAYuMi_-_rev00_description/meshes/Link1_R_1.stl" scale="0.001 0.001 0.001"/>
    </geometry>
  </collision>
</link>

<link name="Link2_R_1">
  <inertial>
    <origin xyz="0.0178623453666928 -0.025608675859911195 0.06427941959136324" rpy="0 0 0"/>
    <mass value="11.070792495652707"/>
    <inertia ixx="0.055419" iyy="0.054878" izz="0.017919" ixy="-0.001753" iyz="-0.009074" ixz="-0.008688"/>
  </inertial>
  <visual>
    <origin xyz="0.03 -0.012 -0.305832" rpy="0 0 0"/>
    <geometry>
      <mesh filename="package://IRB14050_SAYuMi_-_rev00_description/meshes/Link2_R_1.stl" scale="0.001 0.001 0.001"/>
    </geometry>
    <material name="silver"/>
  </visual>
  <collision>
    <origin xyz="0.03 -0.012 -0.305832" rpy="0 0 0"/>
    <geometry>
      <mesh filename="package://IRB14050_SAYuMi_-_rev00_description/meshes/Link2_R_1.stl" scale="0.001 0.001 0.001"/>
    </geometry>
  </collision>
</link>

<link name="Link3_R_1">
  <inertial>
    <origin xyz="0.01920843697040592 0.025172796851887516 0.04362520410506415" rpy="0 0 0"/>
    <mass value="6.048580949750527"/>
    <inertia ixx="0.017488" iyy="0.019009" izz="0.009359" ixy="-0.001939" iyz="-0.004407" ixz="-0.004228"/>
  </inertial>
  <visual>
    <origin xyz="-0.0 -0.001 -0.478662" rpy="0 0 0"/>
    <geometry>
      <mesh filename="package://IRB14050_SAYuMi_-_rev00_description/meshes/Link3_R_1.stl" scale="0.001 0.001 0.001"/>
    </geometry>
    <material name="silver"/>
  </visual>
  <collision>
    <origin xyz="-0.0 -0.001 -0.478662" rpy="0 0 0"/>
    <geometry>
      <mesh filename="package://IRB14050_SAYuMi_-_rev00_description/meshes/Link3_R_1.stl" scale="0.001 0.001 0.001"/>
    </geometry>
  </collision>
</link>

<link name="Link4_R_1">
  <inertial>
    <origin xyz="0.05593149139157671 -0.02868366102631033 0.02261704759774419" rpy="0 0 0"/>
    <mass value="9.26921022899374"/>
    <inertia ixx="0.014525" iyy="0.041104" izz="0.04023" ixy="-0.007292" iyz="-0.002279" ixz="-0.009077"/>
  </inertial>
  <visual>
    <origin xyz="-0.0405 -0.012 -0.557758" rpy="0 0 0"/>
    <geometry>
      <mesh filename="package://IRB14050_SAYuMi_-_rev00_description/meshes/Link4_R_1.stl" scale="0.001 0.001 0.001"/>
    </geometry>
    <material name="silver"/>
  </visual>
  <collision>
    <origin xyz="-0.0405 -0.012 -0.557758" rpy="0 0 0"/>
    <geometry>
      <mesh filename="package://IRB14050_SAYuMi_-_rev00_description/meshes/Link4_R_1.stl" scale="0.001 0.001 0.001"/>
    </geometry>
  </collision>
</link>

<link name="Link5_R_1">
  <inertial>
    <origin xyz="0.04580787520295618 0.027826320424547954 -0.007443616251315288" rpy="0 0 0"/>
    <mass value="2.6959499165850227"/>
    <inertia ixx="0.002867" iyy="0.005667" izz="0.00619" ixy="-0.001992" iyz="0.000395" ixz="0.001038"/>
  </inertial>
  <visual>
    <origin xyz="-0.205149 0.001 -0.598091" rpy="0 0 0"/>
    <geometry>
      <mesh filename="package://IRB14050_SAYuMi_-_rev00_description/meshes/Link5_R_1.stl" scale="0.001 0.001 0.001"/>
    </geometry>
    <material name="silver"/>
  </visual>
  <collision>
    <origin xyz="-0.205149 0.001 -0.598091" rpy="0 0 0"/>
    <geometry>
      <mesh filename="package://IRB14050_SAYuMi_-_rev00_description/meshes/Link5_R_1.stl" scale="0.001 0.001 0.001"/>
    </geometry>
  </collision>
</link>

<link name="Link6_R_1">
  <inertial>
    <origin xyz="-0.01243115833760261 -0.03641924839255436 0.011234978096234638" rpy="0 0 0"/>
    <mass value="3.6915533716806794"/>
    <inertia ixx="0.003891" iyy="0.004078" izz="0.003737" ixy="0.000141" iyz="-0.000212" ixz="6.5e-05"/>
  </inertial>
  <visual>
    <origin xyz="-0.305514 -0.026012 -0.571002" rpy="0 0 0"/>
    <geometry>
      <mesh filename="package://IRB14050_SAYuMi_-_rev00_description/meshes/Link6_R_1.stl" scale="0.001 0.001 0.001"/>
    </geometry>
    <material name="silver"/>
  </visual>
  <collision>
    <origin xyz="-0.305514 -0.026012 -0.571002" rpy="0 0 0"/>
    <geometry>
      <mesh filename="package://IRB14050_SAYuMi_-_rev00_description/meshes/Link6_R_1.stl" scale="0.001 0.001 0.001"/>
    </geometry>
  </collision>
</link>

<link name="Link7_R_1">
  <inertial>
    <origin xyz="0.0003534835414897852 1.06031163510992e-05 3.828102717007287e-05" rpy="0 0 0"/>
    <mass value="0.240688664570473"/>
    <inertia ixx="6.8e-05" iyy="5.7e-05" izz="5.7e-05" ixy="-0.0" iyz="-0.0" ixz="-0.0"/>
  </inertial>
  <visual>
    <origin xyz="-0.33035 0.001 -0.598141" rpy="0 0 0"/>
    <geometry>
      <mesh filename="package://IRB14050_SAYuMi_-_rev00_description/meshes/Link7_R_1.stl" scale="0.001 0.001 0.001"/>
    </geometry>
    <material name="silver"/>
  </visual>
  <collision>
    <origin xyz="-0.33035 0.001 -0.598141" rpy="0 0 0"/>
    <geometry>
      <mesh filename="package://IRB14050_SAYuMi_-_rev00_description/meshes/Link7_R_1.stl" scale="0.001 0.001 0.001"/>
    </geometry>
  </collision>
</link>

<joint name="j1" type="continuous">
  <origin xyz="0.0 0.0 0.173832" rpy="0 0 0"/>
  <parent link="base_link"/>
  <child link="Link1_R_1"/>
  <axis xyz="0.0 0.0 -1.0"/>
</joint>

<joint name="j2" type="continuous">
  <origin xyz="-0.03 0.012 0.132" rpy="0 0 0"/>
  <parent link="Link1_R_1"/>
  <child link="Link2_R_1"/>
  <axis xyz="0.0 1.0 0.0"/>
</joint>

<joint name="j3" type="continuous">
  <origin xyz="0.03 -0.011 0.17283" rpy="0 0 0"/>
  <parent link="Link2_R_1"/>
  <child link="Link3_R_1"/>
  <axis xyz="-0.0 -0.0 1.0"/>
</joint>

<joint name="j4" type="continuous">
  <origin xyz="0.0405 0.011 0.079096" rpy="0 0 0"/>
  <parent link="Link3_R_1"/>
  <child link="Link4_R_1"/>
  <axis xyz="-0.0 -1.0 -0.0"/>
</joint>

<joint name="j5" type="continuous">
  <origin xyz="0.164649 -0.013 0.040333" rpy="0 0 0"/>
  <parent link="Link4_R_1"/>
  <child link="Link5_R_1"/>
  <axis xyz="-0.999999 0.0 0.00101"/>
</joint>

<joint name="j6" type="continuous">
  <origin xyz="0.100365 0.027012 -0.027089" rpy="0 0 0"/>
  <parent link="Link5_R_1"/>
  <child link="Link6_R_1"/>
  <axis xyz="0.0 1.0 0.000441"/>
</joint>

<joint name="j7" type="continuous">
  <origin xyz="0.024836 -0.027012 0.027139" rpy="0 0 0"/>
  <parent link="Link6_R_1"/>
  <child link="Link7_R_1"/>
  <axis xyz="-0.999982 3e-06 -0.00607"/>
</joint>

</robot>
