<?xml version="1.0" ?>
<robot name="IRB1200H_5-90-STD">

<link name="base_link">
  <inertial>
    <origin xyz="-0.023635021150547376 0.0004753411198600048 0.11218944380427551" rpy="0 0 0"/>
    <mass value="83.56281675930393"/>
    <inertia ixx="0.579272" iyy="0.781174" izz="0.698162" ixy="0.004319" iyz="-0.001283" ixz="-0.00506"/>
  </inertial>
  <visual>
    <origin xyz="0 0 0" rpy="0 0 0"/>
    <geometry>
      <mesh filename="package://IRB1200H_5-90-STD_description/meshes/base_link.stl" scale="0.001 0.001 0.001"/>
    </geometry>
    <material name="silver"/>
  </visual>
  <collision>
    <origin xyz="0 0 0" rpy="0 0 0"/>
    <geometry>
      <mesh filename="package://IRB1200H_5-90-STD_description/meshes/base_link.stl" scale="0.001 0.001 0.001"/>
    </geometry>
  </collision>
</link>

<link name="link_1_1">
  <inertial>
    <origin xyz="-0.00321441381731796 0.00043113028566128483 0.10222696949562446" rpy="0 0 0"/>
    <mass value="47.66891611618349"/>
    <inertia ixx="0.595702" iyy="0.377702" izz="0.434187" ixy="-0.000172" iyz="0.000732" ixz="-0.004245"/>
  </inertial>
  <visual>
    <origin xyz="0.0 0.0 -0.219" rpy="0 0 0"/>
    <geometry>
      <mesh filename="package://IRB1200H_5-90-STD_description/meshes/link_1_1.stl" scale="0.001 0.001 0.001"/>
    </geometry>
    <material name="silver"/>
  </visual>
  <collision>
    <origin xyz="0.0 0.0 -0.219" rpy="0 0 0"/>
    <geometry>
      <mesh filename="package://IRB1200H_5-90-STD_description/meshes/link_1_1.stl" scale="0.001 0.001 0.001"/>
    </geometry>
  </collision>
</link>

<link name="link_2_1">
  <inertial>
    <origin xyz="-0.01233108657315479 -0.061156507612509445 0.2184644524959074" rpy="0 0 0"/>
    <mass value="62.596941650298746"/>
    <inertia ixx="2.095914" iyy="1.92136" izz="0.339085" ixy="0.00046" iyz="0.0027" ixz="-0.008483"/>
  </inertial>
  <visual>
    <origin xyz="0.0 -0.06 -0.3991" rpy="0 0 0"/>
    <geometry>
      <mesh filename="package://IRB1200H_5-90-STD_description/meshes/link_2_1.stl" scale="0.001 0.001 0.001"/>
    </geometry>
    <material name="silver"/>
  </visual>
  <collision>
    <origin xyz="0.0 -0.06 -0.3991" rpy="0 0 0"/>
    <geometry>
      <mesh filename="package://IRB1200H_5-90-STD_description/meshes/link_2_1.stl" scale="0.001 0.001 0.001"/>
    </geometry>
  </collision>
</link>

<link name="link_3_1">
  <inertial>
    <origin xyz="0.09811895116802803 -0.06379568686425939 0.03502819908986721" rpy="0 0 0"/>
    <mass value="50.251919251788294"/>
    <inertia ixx="0.15986" iyy="0.614625" izz="0.56594" ixy="0.000967" iyz="0.000343" ixz="-0.040913"/>
  </inertial>
  <visual>
    <origin xyz="-0.0 -0.064 -0.8471" rpy="0 0 0"/>
    <geometry>
      <mesh filename="package://IRB1200H_5-90-STD_description/meshes/link_3_1.stl" scale="0.001 0.001 0.001"/>
    </geometry>
    <material name="silver"/>
  </visual>
  <collision>
    <origin xyz="-0.0 -0.064 -0.8471" rpy="0 0 0"/>
    <geometry>
      <mesh filename="package://IRB1200H_5-90-STD_description/meshes/link_3_1.stl" scale="0.001 0.001 0.001"/>
    </geometry>
  </collision>
</link>

<link name="link_4_1">
  <inertial>
    <origin xyz="0.07074254364387844 0.0016278688336306337 0.0016065194252506965" rpy="0 0 0"/>
    <mass value="14.103086555281287"/>
    <inertia ixx="0.029391" iyy="0.05769" izz="0.061943" ixy="-0.001377" iyz="-1e-05" ixz="0.000485"/>
  </inertial>
  <visual>
    <origin xyz="-0.2885 -0.0 -0.888589" rpy="0 0 0"/>
    <geometry>
      <mesh filename="package://IRB1200H_5-90-STD_description/meshes/link_4_1.stl" scale="0.001 0.001 0.001"/>
    </geometry>
    <material name="silver"/>
  </visual>
  <collision>
    <origin xyz="-0.2885 -0.0 -0.888589" rpy="0 0 0"/>
    <geometry>
      <mesh filename="package://IRB1200H_5-90-STD_description/meshes/link_4_1.stl" scale="0.001 0.001 0.001"/>
    </geometry>
  </collision>
</link>

<link name="link_5_1">
  <inertial>
    <origin xyz="0.013857332914444742 -0.027942297667688586 6.637616500093646e-05" rpy="0 0 0"/>
    <mass value="4.542326712154526"/>
    <inertia ixx="0.003479" iyy="0.008928" izz="0.007834" ixy="-0.000177" iyz="-4e-06" ixz="1.2e-05"/>
  </inertial>
  <visual>
    <origin xyz="-0.450991 -0.0255 -0.8891" rpy="0 0 0"/>
    <geometry>
      <mesh filename="package://IRB1200H_5-90-STD_description/meshes/link_5_1.stl" scale="0.001 0.001 0.001"/>
    </geometry>
    <material name="silver"/>
  </visual>
  <collision>
    <origin xyz="-0.450991 -0.0255 -0.8891" rpy="0 0 0"/>
    <geometry>
      <mesh filename="package://IRB1200H_5-90-STD_description/meshes/link_5_1.stl" scale="0.001 0.001 0.001"/>
    </geometry>
  </collision>
</link>

<link name="link_6_1">
  <inertial>
    <origin xyz="0.002845713618856882 7.306126168841773e-08 -0.0003669972967227375" rpy="0 0 0"/>
    <mass value="0.03668180966446797"/>
    <inertia ixx="1e-05" iyy="5e-06" izz="5e-06" ixy="0.0" iyz="-0.0" ixz="-0.0"/>
  </inertial>
  <visual>
    <origin xyz="-0.5365 1.4e-05 -0.889112" rpy="0 0 0"/>
    <geometry>
      <mesh filename="package://IRB1200H_5-90-STD_description/meshes/link_6_1.stl" scale="0.001 0.001 0.001"/>
    </geometry>
    <material name="silver"/>
  </visual>
  <collision>
    <origin xyz="-0.5365 1.4e-05 -0.889112" rpy="0 0 0"/>
    <geometry>
      <mesh filename="package://IRB1200H_5-90-STD_description/meshes/link_6_1.stl" scale="0.001 0.001 0.001"/>
    </geometry>
  </collision>
</link>

<joint name="j1" type="continuous">
  <origin xyz="0.0 0.0 0.219" rpy="0 0 0"/>
  <parent link="base_link"/>
  <child link="link_1_1"/>
  <axis xyz="0.0 0.0 -1.0"/>
</joint>

<joint name="j2" type="continuous">
  <origin xyz="0.0 0.06 0.1801" rpy="0 0 0"/>
  <parent link="link_1_1"/>
  <child link="link_2_1"/>
  <axis xyz="0.0 -1.0 0.0"/>
</joint>

<joint name="j3" type="continuous">
  <origin xyz="0.0 0.004 0.448" rpy="0 0 0"/>
  <parent link="link_2_1"/>
  <child link="link_3_1"/>
  <axis xyz="0.0 -1.0 0.0"/>
</joint>

<joint name="j4" type="continuous">
  <origin xyz="0.2885 -0.064 0.041489" rpy="0 0 0"/>
  <parent link="link_3_1"/>
  <child link="link_4_1"/>
  <axis xyz="1.0 0.0 0.0"/>
</joint>

<joint name="j5" type="continuous">
  <origin xyz="0.162491 0.0255 0.000511" rpy="0 0 0"/>
  <parent link="link_4_1"/>
  <child link="link_5_1"/>
  <axis xyz="0.0 -1.0 0.0"/>
</joint>

<joint name="j6" type="continuous">
  <origin xyz="0.085509 -0.025514 1.2e-05" rpy="0 0 0"/>
  <parent link="link_5_1"/>
  <child link="link_6_1"/>
  <axis xyz="1.0 0.0 0.0"/>
</joint>

</robot>
