<?xml version="1.0" ?>
<robot name="IRB920T_6kg_450_180_STD">

<link name="base_link">
  <inertial>
    <origin xyz="-0.025007128631782737 4.8316998944871165e-06 0.0942820943103721" rpy="0 0 0"/>
    <mass value="41.12593814105158"/>
    <inertia ixx="0.182723" iyy="0.263419" izz="0.209732" ixy="5.3e-05" iyz="2e-06" ixz="0.005906"/>
  </inertial>
  <visual>
    <origin xyz="0 0 0" rpy="0 0 0"/>
    <geometry>
      <mesh filename="meshes/base_link.stl" scale="0.001 0.001 0.001"/>
    </geometry>
  </visual>
  <collision>
    <origin xyz="0 0 0" rpy="0 0 0"/>
    <geometry>
      <mesh filename="meshes/base_link.stl" scale="0.001 0.001 0.001"/>
    </geometry>
  </collision>
</link>

<link name="link_1">
  <inertial>
    <origin xyz="0.08115257258737836 4.78068739670782e-05 0.0457660214106653" rpy="0 0 0"/>
    <mass value="25.677563367507343"/>
    <inertia ixx="0.05341" iyy="0.223323" izz="0.252796" ixy="1.4e-05" iyz="4.5e-05" ixz="-0.011896"/>
  </inertial>
  <visual>
    <origin xyz="0.00025 -2e-06 -0.1914" rpy="0 0 0"/>
    <geometry>
      <mesh filename="meshes/link_1.stl" scale="0.001 0.001 0.001"/>
    </geometry>
  </visual>
  <collision>
    <origin xyz="0.00025 -2e-06 -0.1914" rpy="0 0 0"/>
    <geometry>
      <mesh filename="meshes/link_1.stl" scale="0.001 0.001 0.001"/>
    </geometry>
  </collision>
</link>

<link name="link_2">
  <inertial>
    <origin xyz="0.097869480002094 2.829652201639198e-06 0.08518139176786854" rpy="0 0 0"/>
    <mass value="75.7740500377449"/>
    <inertia ixx="0.309324" iyy="1.206997" izz="1.132455" ixy="1.3e-05" iyz="1.8e-05" ixz="0.072377"/>
  </inertial>
  <visual>
    <origin xyz="-0.191498 -0.0 -0.2785" rpy="0 0 0"/>
    <geometry>
      <mesh filename="meshes/link_2.stl" scale="0.001 0.001 0.001"/>
    </geometry>
  </visual>
  <collision>
    <origin xyz="-0.191498 -0.0 -0.2785" rpy="0 0 0"/>
    <geometry>
      <mesh filename="meshes/link_2.stl" scale="0.001 0.001 0.001"/>
    </geometry>
  </collision>
</link>

<link name="link_3">
  <inertial>
    <origin xyz="-7.554934788289724e-05 -7.453270582378933e-05 -0.1760046819511616" rpy="0 0 0"/>
    <mass value="0.6594614836495646"/>
    <inertia ixx="0.011651" iyy="0.011651" izz="7.7e-05" ixy="1e-06" iyz="-0.0" ixz="1e-06"/>
  </inertial>
  <visual>
    <origin xyz="-0.45 0.0 -0.5835" rpy="0 0 0"/>
    <geometry>
      <mesh filename="meshes/link_3.stl" scale="0.001 0.001 0.001"/>
    </geometry>
  </visual>
  <collision>
    <origin xyz="-0.45 0.0 -0.5835" rpy="0 0 0"/>
    <geometry>
      <mesh filename="meshes/link_3.stl" scale="0.001 0.001 0.001"/>
    </geometry>
  </collision>
</link>

<joint name="joint_1" type="continuous">
  <origin xyz="-0.00025 2e-06 0.1914" rpy="0 0 0"/>
  <parent link="base_link"/>
  <child link="link_1"/>
  <axis xyz="0.0 0.0 1.0"/>
  <limit lower="-2.61799" upper="2.61799" effort="0.0" velocity="0.0"/>
</joint>

<joint name="joint_2" type="continuous">
  <origin xyz="0.191748 -2e-06 0.0871" rpy="0 0 0"/>
  <parent link="link_1"/>
  <child link="link_2"/>
  <axis xyz="0.0 0.0 1.0"/>
  <limit lower="-2.53073" upper="2.53073" effort="0.0" velocity="0.0"/>
</joint>

<joint name="joint_3" type="prismatic">
  <origin xyz="0.258502 -0.0 0.305" rpy="0 0 0"/>
  <parent link="link_2"/>
  <child link="link_3"/>
  <axis xyz="0.0 0.0 1.0"/>
  <limit lower="0.0" upper="0.145" effort="0.0" velocity="0.0"/>
</joint>

<link name="flange">
  <inertial>
    <origin xyz="0 0 0" rpy="0 0 0"/>
    <mass value="0.1"/>
    <inertia ixx="0.001" iyy="0.001" izz="0.001" ixy="0" iyz="0" ixz="0"/>
  </inertial>
</link>

<link name="tool0">
  <inertial>
    <origin xyz="0 0 0" rpy="0 0 0"/>
    <mass value="0.1"/>
    <inertia ixx="0.001" iyy="0.001" izz="0.001" ixy="0" iyz="0" ixz="0"/>
  </inertial>
</link>

<joint name="joint_4" type="continuous">
  <origin xyz="0 0 0" rpy="0 0 0"/>
  <parent link="link_3"/>
  <child link="flange"/>
  <axis xyz="0.0 0.0 1.0"/>
  <limit lower="-6.98132" upper="6.98132" effort="0.0" velocity="0.0"/>
</joint>

<joint name="joint_tool0" type="fixed">
  <origin xyz="0.0 0.0 0.0" rpy="0 0 0"/>
  <parent link="flange"/>
  <child link="tool0"/>
</joint>

</robot>