<?xml version="1.0" ?>
<robot name="Irbpk-600_D1200-L1600_IRC5_rev02_CAD" xmlns:xacro="http://www.ros.org/wiki/xacro">

<xacro:include filename="$(find Irbpk-600_D1200-L1600_IRC5_rev02_CAD_description)/urdf/materials.xacro" />
<xacro:include filename="$(find Irbpk-600_D1200-L1600_IRC5_rev02_CAD_description)/urdf/Irbpk-600_D1200-L1600_IRC5_rev02_CAD.trans" />
<xacro:include filename="$(find Irbpk-600_D1200-L1600_IRC5_rev02_CAD_description)/urdf/Irbpk-600_D1200-L1600_IRC5_rev02_CAD.gazebo" />
<link name="base_link">
  <inertial>
    <origin xyz="0.3336227624041389 -0.21471993872894346 0.5144999087565431" rpy="0 0 0"/>
    <mass value="6023.081275897608"/>
    <inertia ixx="10894.677826" iyy="2486.703559" izz="10830.366024" ixy="-1027.288729" iyz="-1271.001654" ixz="-670.763156"/>
  </inertial>
  <visual>
    <origin xyz="0 0 0" rpy="0 0 0"/>
    <geometry>
      <mesh filename="package://Irbpk-600_D1200-L1600_IRC5_rev02_CAD_description/meshes/base_link.stl" scale="0.001 0.001 0.001"/>
    </geometry>
    <material name="silver"/>
  </visual>
  <collision>
    <origin xyz="0 0 0" rpy="0 0 0"/>
    <geometry>
      <mesh filename="package://Irbpk-600_D1200-L1600_IRC5_rev02_CAD_description/meshes/base_link.stl" scale="0.001 0.001 0.001"/>
    </geometry>
  </collision>
</link>

<link name="Component1_1">
  <inertial>
    <origin xyz="3.5305937964302814e-06 -1.1004597804902332 2.0898374075706272e-07" rpy="0 0 0"/>
    <mass value="4222.428940897072"/>
    <inertia ixx="3646.451171" iyy="893.970985" izz="3705.483671" ixy="-0.015072" iyz="-5.8e-05" ixz="265.262823"/>
  </inertial>
  <visual>
    <origin xyz="-0.633753 -0.496 -1.37" rpy="0 0 0"/>
    <geometry>
      <mesh filename="package://Irbpk-600_D1200-L1600_IRC5_rev02_CAD_description/meshes/Component1_1.stl" scale="0.001 0.001 0.001"/>
    </geometry>
    <material name="silver"/>
  </visual>
  <collision>
    <origin xyz="-0.633753 -0.496 -1.37" rpy="0 0 0"/>
    <geometry>
      <mesh filename="package://Irbpk-600_D1200-L1600_IRC5_rev02_CAD_description/meshes/Component1_1.stl" scale="0.001 0.001 0.001"/>
    </geometry>
  </collision>
</link>

<link name="Component8_1">
  <inertial>
    <origin xyz="0.0009281362035320484 0.017632134399484654 -0.0006141312434708723" rpy="0 0 0"/>
    <mass value="21.250303833372335"/>
    <inertia ixx="0.229369" iyy="0.446816" izz="0.230477" ixy="-0.000486" iyz="0.000322" ixz="0.001306"/>
  </inertial>
  <visual>
    <origin xyz="-1.267506 -0.001 -0.950528" rpy="0 0 0"/>
    <geometry>
      <mesh filename="package://Irbpk-600_D1200-L1600_IRC5_rev02_CAD_description/meshes/Component8_1.stl" scale="0.001 0.001 0.001"/>
    </geometry>
    <material name="silver"/>
  </visual>
  <collision>
    <origin xyz="-1.267506 -0.001 -0.950528" rpy="0 0 0"/>
    <geometry>
      <mesh filename="package://Irbpk-600_D1200-L1600_IRC5_rev02_CAD_description/meshes/Component8_1.stl" scale="0.001 0.001 0.001"/>
    </geometry>
  </collision>
</link>

<link name="Component6_1">
  <inertial>
    <origin xyz="-0.000927686661294599 0.01763213439947378 0.0006141312436094282" rpy="0 0 0"/>
    <mass value="21.250303833372307"/>
    <inertia ixx="0.229369" iyy="0.446816" izz="0.230477" ixy="0.000486" iyz="-0.000322" ixz="0.001306"/>
  </inertial>
  <visual>
    <origin xyz="0.0 -0.001 -1.789472" rpy="0 0 0"/>
    <geometry>
      <mesh filename="package://Irbpk-600_D1200-L1600_IRC5_rev02_CAD_description/meshes/Component6_1.stl" scale="0.001 0.001 0.001"/>
    </geometry>
    <material name="silver"/>
  </visual>
  <collision>
    <origin xyz="0.0 -0.001 -1.789472" rpy="0 0 0"/>
    <geometry>
      <mesh filename="package://Irbpk-600_D1200-L1600_IRC5_rev02_CAD_description/meshes/Component6_1.stl" scale="0.001 0.001 0.001"/>
    </geometry>
  </collision>
</link>

<joint name="j1" type="continuous">
  <origin xyz="0.633753 0.496 1.37" rpy="0 0 0"/>
  <parent link="base_link"/>
  <child link="Component1_1"/>
  <axis xyz="0.0 -1.0 0.0"/>
</joint>

<joint name="j2" type="continuous">
  <origin xyz="0.633753 -0.495 -0.419472" rpy="0 0 0"/>
  <parent link="Component1_1"/>
  <child link="Component8_1"/>
  <axis xyz="-0.0 -1.0 0.0"/>
</joint>

<joint name="j3" type="continuous">
  <origin xyz="-0.633753 -0.495 0.419472" rpy="0 0 0"/>
  <parent link="Component1_1"/>
  <child link="Component6_1"/>
  <axis xyz="0.0 -1.0 -0.0"/>
</joint>

</robot>
