<?xml version="1.0" ?>
<robot name="IRB1200_5_90_STD">

<link name="base_link">
  <inertial>
    <origin xyz="-0.023637177591968993 0.0004754421976295026 0.11218867494644966" rpy="0 0 0"/>
    <mass value="83.56354769083484"/>
    <inertia ixx="0.579276" iyy="0.781207" izz="0.698188" ixy="0.004313" iyz="-0.001283" ixz="-0.005073"/>
  </inertial>
  <visual>
    <origin xyz="0 0 0" rpy="0 0 0"/>
    <geometry>
      <mesh filename="meshes/base_link.stl" scale="0.001 0.001 0.001"/>
    </geometry>
  </visual>
  <collision>
    <origin xyz="0 0 0" rpy="0 0 0"/>
    <geometry>
      <mesh filename="meshes/base_link.stl" scale="0.001 0.001 0.001"/>
    </geometry>
  </collision>
</link>

<link name="link_1">
  <inertial>
    <origin xyz="-0.0032935657511956266 0.0004389797692321195 0.1023344133013073" rpy="0 0 0"/>
    <mass value="47.59365241562889"/>
    <inertia ixx="0.595053" iyy="0.377165" izz="0.433688" ixy="-0.000188" iyz="0.000756" ixz="-0.004502"/>
  </inertial>
  <visual>
    <origin xyz="-0.0 -0.0 -0.219" rpy="0 0 0"/>
    <geometry>
      <mesh filename="meshes/link_1.stl" scale="0.001 0.001 0.001"/>
    </geometry>
  </visual>
  <collision>
    <origin xyz="-0.0 -0.0 -0.219" rpy="0 0 0"/>
    <geometry>
      <mesh filename="meshes/link_1.stl" scale="0.001 0.001 0.001"/>
    </geometry>
  </collision>
</link>

<link name="link_2">
  <inertial>
    <origin xyz="-0.04459016571148093 0.10585337629572772 0.20122835114038373" rpy="0 0 0"/>
    <mass value="0.0002346193667311735"/>
    <inertia ixx="1e-06" iyy="1e-06" izz="0.0" ixy="-0.0" iyz="-0.0" ixz="-0.0"/>
  </inertial>
  <visual>
    <origin xyz="-0.0 0.0605 -0.3991" rpy="0 0 0"/>
    <geometry>
      <mesh filename="meshes/link_2.stl" scale="0.001 0.001 0.001"/>
    </geometry>
  </visual>
  <collision>
    <origin xyz="-0.0 0.0605 -0.3991" rpy="0 0 0"/>
    <geometry>
      <mesh filename="meshes/link_2.stl" scale="0.001 0.001 0.001"/>
    </geometry>
  </collision>
</link>

<link name="link_3">
  <inertial>
    <origin xyz="0.09791045075109603 0.05809893106914741 0.03486958303185361" rpy="0 0 0"/>
    <mass value="50.4799691302992"/>
    <inertia ixx="0.160642" iyy="0.616313" izz="0.567714" ixy="0.000817" iyz="0.000117" ixz="-0.04111"/>
  </inertial>
  <visual>
    <origin xyz="-0.0 0.058 -0.8471" rpy="0 0 0"/>
    <geometry>
      <mesh filename="meshes/link_3.stl" scale="0.001 0.001 0.001"/>
    </geometry>
  </visual>
  <collision>
    <origin xyz="-0.0 0.058 -0.8471" rpy="0 0 0"/>
    <geometry>
      <mesh filename="meshes/link_3.stl" scale="0.001 0.001 0.001"/>
    </geometry>
  </collision>
</link>

<link name="link_4">
  <inertial>
    <origin xyz="0.076261239206589 0.0025635992899178195 0.0007346564679856504" rpy="0 0 0"/>
    <mass value="13.07948314741883"/>
    <inertia ixx="0.027901" iyy="0.049444" izz="0.053614" ixy="-0.001885" iyz="-1.3e-05" ixz="0.000399"/>
  </inertial>
  <visual>
    <origin xyz="-0.2885 -0.0 -0.8891" rpy="0 0 0"/>
    <geometry>
      <mesh filename="meshes/link_4.stl" scale="0.001 0.001 0.001"/>
    </geometry>
  </visual>
  <collision>
    <origin xyz="-0.2885 -0.0 -0.8891" rpy="0 0 0"/>
    <geometry>
      <mesh filename="meshes/link_4.stl" scale="0.001 0.001 0.001"/>
    </geometry>
  </collision>
</link>

<link name="link_5">
  <inertial>
    <origin xyz="0.009412902573906423 0.026847797041943774 -2.972957832358958e-06" rpy="0 0 0"/>
    <mass value="4.044605310431727"/>
    <inertia ixx="0.002998" iyy="0.007142" izz="0.006032" ixy="-7.2e-05" iyz="0.0" ixz="0.0"/>
  </inertial>
  <visual>
    <origin xyz="-0.451 0.0285 -0.8891" rpy="0 0 0"/>
    <geometry>
      <mesh filename="meshes/link_5.stl" scale="0.001 0.001 0.001"/>
    </geometry>
  </visual>
  <collision>
    <origin xyz="-0.451 0.0285 -0.8891" rpy="0 0 0"/>
    <geometry>
      <mesh filename="meshes/link_5.stl" scale="0.001 0.001 0.001"/>
    </geometry>
  </collision>
</link>

<link name="link_6">
  <inertial>
    <origin xyz="0.0024818942259828836 -8.835029930799617e-13 -0.00036127714748035444" rpy="0 0 0"/>
    <mass value="0.03376885335108457"/>
    <inertia ixx="8e-06" iyy="4e-06" izz="4e-06" ixy="0.0" iyz="0.0" ixz="0.0"/>
  </inertial>
  <visual>
    <origin xyz="-0.528 0.0 -0.8891" rpy="0 0 0"/>
    <geometry>
      <mesh filename="meshes/link_6.stl" scale="0.001 0.001 0.001"/>
    </geometry>
  </visual>
  <collision>
    <origin xyz="-0.528 0.0 -0.8891" rpy="0 0 0"/>
    <geometry>
      <mesh filename="meshes/link_6.stl" scale="0.001 0.001 0.001"/>
    </geometry>
  </collision>
</link>

<joint name="joint_1" type="revolute">
  <origin xyz="0.0 0.0 0.219" rpy="0 0 0"/>
  <parent link="base_link"/>
  <child link="link_1"/>
  <axis xyz="0.0 0.0 1.0"/>
  <limit lower="-2.9671" upper="2.9671" effort="0" velocity="5.0265" />
</joint>

<joint name="joint_2" type="revolute">
  <origin xyz="0.0 -0.0605 0.1801" rpy="0 0 0"/>
  <parent link="link_1"/>
  <child link="link_2"/>
  <axis xyz="0.0 1.0 0.0"/>
  <limit lower="-1.7453" upper="2.2689" effort="0" velocity="3.9095" />
</joint>

<joint name="joint_3" type="revolute">
  <origin xyz="0.0 0.0025 0.448" rpy="0 0 0"/>
  <parent link="link_2"/>
  <child link="link_3"/>
  <axis xyz="0.0 -1.0 0.0"/>
  <limit lower="-3.4907" upper="1.2217" effort="0" velocity="5.1836" />
</joint>

<joint name="joint_4" type="revolute">
  <origin xyz="0.2885 0.058 0.042" rpy="0 0 0"/>
  <parent link="link_3"/>
  <child link="link_4"/>
  <axis xyz="-1.0 0.0 0.0"/>
  <limit lower="-4.7124" upper="4.7124" effort="0" velocity="6.9813" />
</joint>

<joint name="joint_5" type="revolute">
  <origin xyz="0.1625 -0.0285 0.0" rpy="0 0 0"/>
  <parent link="link_4"/>
  <child link="link_5"/>
  <axis xyz="0.0 1.0 0.0"/>
  <limit lower="-2.2689" upper="2.2689" effort="0" velocity="7.0686" />
</joint>

<joint name="joint_6" type="revolute">
  <origin xyz="0.077 0.0285 0.0" rpy="0 0 0"/>
  <parent link="link_5"/>
  <child link="link_6"/>
  <axis xyz="1.0 0.0 0.0"/>
  <limit lower="-6.9813" upper="6.9813" effort="0" velocity="10.4719" />
</joint>

<link name="flange">
  <inertial>
    <origin xyz="0 0 0" rpy="0 0 0"/>
    <mass value="0.01"/>
    <inertia ixx="1e-06" iyy="1e-06" izz="1e-06" ixy="0" iyz="0" ixz="0"/>
  </inertial>
</link>

<link name="tool0">
  <inertial>
    <origin xyz="0 0 0" rpy="0 0 0"/>
    <mass value="0.01"/>
    <inertia ixx="1e-06" iyy="1e-06" izz="1e-06" ixy="0" iyz="0" ixz="0"/>
  </inertial>
</link>

<joint name="joint_6-flange" type="fixed">
  <origin xyz="0.005 0 0" rpy="0 1.57 0"/>
  <parent link="link_6"/>
  <child link="flange"/>
</joint>

<joint name="flange-tool0" type="fixed">
  <origin xyz="0 0 0" rpy="0 0 0"/>
  <parent link="flange"/>
  <child link="tool0"/>
</joint>

</robot>