<?xml version="1.0"?>
<robot name="Irbpa_250_D1000_IRC5_rev02_CAD">

<link name="base_link">
  <inertial>
    <origin xyz="0.8285107796272847 0.0012219899578449352 0.5370026604000335" rpy="0 0 0"/>
    <mass value="1106.0690804578326"/>
    <inertia ixx="159.054625" iyy="166.987389" izz="32.2919" ixy="-0.172279" iyz="-0.474836" ixz="-14.206829"/>
  </inertial>
  <visual>
    <origin xyz="0 0 0" rpy="0 0 0"/>
    <geometry>
      <mesh filename="meshes/base_link.stl" scale="0.001 0.001 0.001"/>
    </geometry>
  </visual>
  <collision>
    <origin xyz="0 0 0" rpy="0 0 0"/>
    <geometry>
      <mesh filename="meshes/base_link.stl" scale="0.001 0.001 0.001"/>
    </geometry>
  </collision>
</link>

<link name="Irbpa_250_D1000_IRC5_rev02_Arm250AB_CAD_1">
  <inertial>
    <origin xyz="-0.48798652287282596 -0.002958286618985653 -0.23701597438616928" rpy="0 0 0"/>
    <mass value="217.74567622168203"/>
    <inertia ixx="5.18673" iyy="17.406649" izz="14.435722" ixy="-0.024266" iyz="-0.115807" ixz="-5.50859"/>
  </inertial>
  <visual>
    <origin xyz="-0.6825 -0.0 -1.02" rpy="0 0 0"/>
    <geometry>
      <mesh filename="meshes/Irbpa_250_D1000_IRC5_rev02_Arm250AB_CAD_1.stl" scale="0.001 0.001 0.001"/>
    </geometry>
  </visual>
  <collision>
    <origin xyz="-0.6825 -0.0 -1.02" rpy="0 0 0"/>
    <geometry>
      <mesh filename="meshes/Irbpa_250_D1000_IRC5_rev02_Arm250AB_CAD_1.stl" scale="0.001 0.001 0.001"/>
    </geometry>
  </collision>
</link>

<link name="Irbpa_250_D1000_IRC5_rev02_platter_d350_CAD_1">
  <inertial>
    <origin xyz="-0.0004051961273977961 1.0394628322001757e-08 0.02809458902719031" rpy="0 0 0"/>
    <mass value="9.835889620455225"/>
    <inertia ixx="0.066765" iyy="0.067076" izz="0.131981" ixy="-0.0" iyz="0.0" ixz="-9.3e-05"/>
  </inertial>
  <visual>
    <origin xyz="0.0 -0.0 -0.8615" rpy="0 0 0"/>
    <geometry>
      <mesh filename="meshes/Irbpa_250_D1000_IRC5_rev02_platter_d350_CAD_1.stl" scale="0.001 0.001 0.001"/>
    </geometry>
  </visual>
  <collision>
    <origin xyz="0.0 -0.0 -0.8615" rpy="0 0 0"/>
    <geometry>
      <mesh filename="meshes/Irbpa_250_D1000_IRC5_rev02_platter_d350_CAD_1.stl" scale="0.001 0.001 0.001"/>
    </geometry>
  </collision>
</link>

<joint name="j1" type="continuous">
  <origin xyz="0.6825 0.0 1.02" rpy="0 0 0"/>
  <parent link="base_link"/>
  <child link="Irbpa_250_D1000_IRC5_rev02_Arm250AB_CAD_1"/>
  <axis xyz="-1.0 -0.0 -0.0"/>
</joint>

<joint name="j2" type="continuous">
  <origin xyz="-0.6825 0.0 -0.1585" rpy="0 0 0"/>
  <parent link="Irbpa_250_D1000_IRC5_rev02_Arm250AB_CAD_1"/>
  <child link="Irbpa_250_D1000_IRC5_rev02_platter_d350_CAD_1"/>
  <axis xyz="-0.0 0.0 1.0"/>
</joint>

</robot>