<?xml version="1.0" ?>
<robot name="IRB910INV_550">

<link name="base_link">
  <inertial>
    <origin xyz="-0.03428217335737813 -2.4667588020476706e-07 0.08971070325608167" rpy="0 0 0"/>
    <mass value="47.926347738289834"/>
    <inertia ixx="0.305149" iyy="0.354553" izz="0.217137" ixy="-4e-06" iyz="9.8e-05" ixz="0.004008"/>
  </inertial>
  <visual>
    <origin xyz="0 0 0" rpy="0 0 0"/>
    <geometry>
      <mesh filename="meshes/base_link.stl" scale="0.001 0.001 0.001"/>
    </geometry>
  </visual>
  <collision>
    <origin xyz="0 0 0" rpy="0 0 0"/>
    <geometry>
      <mesh filename="meshes/base_link.stl" scale="0.001 0.001 0.001"/>
    </geometry>
  </collision>
</link>

<link name="Link1_C550_IP54CR_1">
  <inertial>
    <origin xyz="0.19001834496263106 1.2971798160160128e-05 -0.11021715675959742" rpy="0 0 0"/>
    <mass value="47.35022106297793"/>
    <inertia ixx="0.302918" iyy="0.718755" izz="0.514821" ixy="7.2e-05" iyz="-4.1e-05" ixz="0.191541"/>
  </inertial>
  <visual>
    <origin xyz="-0.0 -4e-06 0.0225" rpy="0 0 0"/>
    <geometry>
      <mesh filename="meshes/Link1_C550_IP54CR_1.stl" scale="0.001 0.001 0.001"/>
    </geometry>
  </visual>
  <collision>
    <origin xyz="-0.0 -4e-06 0.0225" rpy="0 0 0"/>
    <geometry>
      <mesh filename="meshes/Link1_C550_IP54CR_1.stl" scale="0.001 0.001 0.001"/>
    </geometry>
  </collision>
</link>

<link name="Link2_C550_IP54CR_1">
  <inertial>
    <origin xyz="-0.1301713720166507 4.3805985255709795e-06 -0.09290145322121324" rpy="0 0 0"/>
    <mass value="60.90584870029004"/>
    <inertia ixx="0.222627" iyy="0.806335" izz="0.734879" ixy="-2.5e-05" iyz="-5e-05" ixz="-0.033018"/>
  </inertial>
  <visual>
    <origin xyz="-0.275 -4e-06 0.281" rpy="0 0 0"/>
    <geometry>
      <mesh filename="meshes/Link2_C550_IP54CR_1.stl" scale="0.001 0.001 0.001"/>
    </geometry>
  </visual>
  <collision>
    <origin xyz="-0.275 -4e-06 0.281" rpy="0 0 0"/>
    <geometry>
      <mesh filename="meshes/Link2_C550_IP54CR_1.stl" scale="0.001 0.001 0.001"/>
    </geometry>
  </collision>
</link>

<link name="Link4_C550_IP54CR_1">
  <inertial>
    <origin xyz="2.314787645762635e-06 3.455104944045238e-06 -0.16788068593611935" rpy="0 0 0"/>
    <mass value="1.2507936056644426"/>
    <inertia ixx="0.030362" iyy="0.030362" izz="0.000213" ixy="-0.0" iyz="1e-06" ixz="1e-06"/>
  </inertial>
  <visual>
    <origin xyz="0.0 0.0 0.158" rpy="0 0 0"/>
    <geometry>
      <mesh filename="meshes/Link4_C550_IP54CR_1.stl" scale="0.001 0.001 0.001"/>
    </geometry>
  </visual>
  <collision>
    <origin xyz="0.0 0.0 0.158" rpy="0 0 0"/>
    <geometry>
      <mesh filename="meshes/Link4_C550_IP54CR_1.stl" scale="0.001 0.001 0.001"/>
    </geometry>
  </collision>
</link>

<joint name="j1" type="revolute">
  <origin xyz="0.0 4e-06 -0.0225" rpy="0 0 0"/>
  <parent link="base_link"/>
  <child link="Link1_C550_IP54CR_1"/>
  <axis xyz="0.0 0.0 -1.0"/>
  <limit lower="-2.61799" upper="2.61799" effort="0.0" velocity="0.0"/>
</joint>

<joint name="j2" type="revolute">
  <origin xyz="0.275 0.0 -0.2585" rpy="0 0 0"/>
  <parent link="Link1_C550_IP54CR_1"/>
  <child link="Link2_C550_IP54CR_1"/>
  <axis xyz="0.0 0.0 -1.0"/>
  <limit lower="-2.53073" upper="2.53073" effort="0.0" velocity="0.0"/>
</joint>

<joint name="Slider_3" type="prismatic">
  <origin xyz="-0.275 -4e-06 0.123" rpy="0 0 0"/>
  <parent link="Link2_C550_IP54CR_1"/>
  <child link="Link4_C550_IP54CR_1"/>
  <axis xyz="0.0 0.0 1.0"/>
  <limit upper="0.0" lower="-0.1" effort="100" velocity="100"/>
</joint>

<joint name="joint_4" type="revolute">
  <origin xyz="0 0 0" rpy="0 0 0"/>
  <parent link="Link4_C550_IP54CR_1"/>
  <child link="flange"/>
  <axis xyz="0.0 0.0 1.0"/>
  <limit lower="-6.98132" upper="6.98132" effort="0.0" velocity="0.0"/>
</joint>

<link name="flange">
  <inertial>
    <origin xyz="0 0 0" rpy="0 0 0"/>
    <mass value="0.1"/>
    <inertia ixx="0.0001" iyy="0.0001" izz="0.0001" ixy="0" iyz="0" ixz="0"/>
  </inertial>
</link>

<link name="tool0">
  <inertial>
    <origin xyz="0 0 0" rpy="0 0 0"/>
    <mass value="0.01"/>
    <inertia ixx="0.00001" iyy="0.00001" izz="0.00001" ixy="0" iyz="0" ixz="0"/>
  </inertial>
</link>

<joint name="joint_tool0" type="fixed">
  <origin xyz="0 0 0" rpy="0 0 0"/>
  <parent link="flange"/>
  <child link="tool0"/>
</joint>

</robot>