<?xml version="1.0" ?>
<robot name="(Unsaved)" xmlns:xacro="http://www.ros.org/wiki/xacro">

<xacro:include filename="$(find (Unsaved)_description)/urdf/materials.xacro" />
<xacro:include filename="$(find (Unsaved)_description)/urdf/(Unsaved).trans" />
<xacro:include filename="$(find (Unsaved)_description)/urdf/(Unsaved).gazebo" />
<link name="base_link">
  <inertial>
    <origin xyz="-0.025007128631782737 4.8316998944871165e-06 0.0942820943103721" rpy="0 0 0"/>
    <mass value="41.12593814105158"/>
    <inertia ixx="0.182723" iyy="0.263419" izz="0.209732" ixy="5.3e-05" iyz="2e-06" ixz="0.005906"/>
  </inertial>
  <visual>
    <origin xyz="0 0 0" rpy="0 0 0"/>
    <geometry>
      <mesh filename="package://(Unsaved)_description/meshes/base_link.stl" scale="0.001 0.001 0.001"/>
    </geometry>
    <material name="silver"/>
  </visual>
  <collision>
    <origin xyz="0 0 0" rpy="0 0 0"/>
    <geometry>
      <mesh filename="package://(Unsaved)_description/meshes/base_link.stl" scale="0.001 0.001 0.001"/>
    </geometry>
  </collision>
</link>

<link name="IRB920T_6kg-450-180-STD_OmniCore_rev00_LINK1_CAD_1">
  <inertial>
    <origin xyz="0.08115257258737836 4.78068739670782e-05 0.0457660214106653" rpy="0 0 0"/>
    <mass value="25.677563367507343"/>
    <inertia ixx="0.05341" iyy="0.223323" izz="0.252796" ixy="1.4e-05" iyz="4.5e-05" ixz="-0.011896"/>
  </inertial>
  <visual>
    <origin xyz="0.00025 -2e-06 -0.1914" rpy="0 0 0"/>
    <geometry>
      <mesh filename="package://(Unsaved)_description/meshes/IRB920T_6kg-450-180-STD_OmniCore_rev00_LINK1_CAD_1.stl" scale="0.001 0.001 0.001"/>
    </geometry>
    <material name="silver"/>
  </visual>
  <collision>
    <origin xyz="0.00025 -2e-06 -0.1914" rpy="0 0 0"/>
    <geometry>
      <mesh filename="package://(Unsaved)_description/meshes/IRB920T_6kg-450-180-STD_OmniCore_rev00_LINK1_CAD_1.stl" scale="0.001 0.001 0.001"/>
    </geometry>
  </collision>
</link>

<link name="IRB920T_6kg-450-180-STD_OmniCore_rev00_LINK2_CAD_1">
  <inertial>
    <origin xyz="0.097869480002094 2.829652201639198e-06 0.08518139176786854" rpy="0 0 0"/>
    <mass value="75.7740500377449"/>
    <inertia ixx="0.309324" iyy="1.206997" izz="1.132455" ixy="1.3e-05" iyz="1.8e-05" ixz="0.072377"/>
  </inertial>
  <visual>
    <origin xyz="-0.191498 -0.0 -0.2785" rpy="0 0 0"/>
    <geometry>
      <mesh filename="package://(Unsaved)_description/meshes/IRB920T_6kg-450-180-STD_OmniCore_rev00_LINK2_CAD_1.stl" scale="0.001 0.001 0.001"/>
    </geometry>
    <material name="silver"/>
  </visual>
  <collision>
    <origin xyz="-0.191498 -0.0 -0.2785" rpy="0 0 0"/>
    <geometry>
      <mesh filename="package://(Unsaved)_description/meshes/IRB920T_6kg-450-180-STD_OmniCore_rev00_LINK2_CAD_1.stl" scale="0.001 0.001 0.001"/>
    </geometry>
  </collision>
</link>

<link name="IRB920T_6kg-450-180-STD_OmniCore_rev00_LINK3_CAD_1">
  <inertial>
    <origin xyz="-7.554934788289724e-05 -7.453270582378933e-05 -0.1760046819511616" rpy="0 0 0"/>
    <mass value="0.6594614836495646"/>
    <inertia ixx="0.011651" iyy="0.011651" izz="7.7e-05" ixy="1e-06" iyz="-0.0" ixz="1e-06"/>
  </inertial>
  <visual>
    <origin xyz="-0.45 0.0 -0.5835" rpy="0 0 0"/>
    <geometry>
      <mesh filename="package://(Unsaved)_description/meshes/IRB920T_6kg-450-180-STD_OmniCore_rev00_LINK3_CAD_1.stl" scale="0.001 0.001 0.001"/>
    </geometry>
    <material name="silver"/>
  </visual>
  <collision>
    <origin xyz="-0.45 0.0 -0.5835" rpy="0 0 0"/>
    <geometry>
      <mesh filename="package://(Unsaved)_description/meshes/IRB920T_6kg-450-180-STD_OmniCore_rev00_LINK3_CAD_1.stl" scale="0.001 0.001 0.001"/>
    </geometry>
  </collision>
</link>

<joint name="Revolute 1" type="continuous">
  <origin xyz="-0.00025 2e-06 0.1914" rpy="0 0 0"/>
  <parent link="base_link"/>
  <child link="IRB920T_6kg-450-180-STD_OmniCore_rev00_LINK1_CAD_1"/>
  <axis xyz="0.0 0.0 1.0"/>
</joint>

<joint name="Revolute 2" type="continuous">
  <origin xyz="0.191748 -2e-06 0.0871" rpy="0 0 0"/>
  <parent link="IRB920T_6kg-450-180-STD_OmniCore_rev00_LINK1_CAD_1"/>
  <child link="IRB920T_6kg-450-180-STD_OmniCore_rev00_LINK2_CAD_1"/>
  <axis xyz="0.0 0.0 1.0"/>
</joint>

<joint name="Slider 3" type="prismatic">
  <origin xyz="0.258502 -0.0 0.305" rpy="0 0 0"/>
  <parent link="IRB920T_6kg-450-180-STD_OmniCore_rev00_LINK2_CAD_1"/>
  <child link="IRB920T_6kg-450-180-STD_OmniCore_rev00_LINK3_CAD_1"/>
  <axis xyz="0.0 0.0 1.0"/>
  <limit upper="0.0" lower="-0.1" effort="100" velocity="100"/>
</joint>

</robot>
