<?xml version="1.0" ?>
<robot name="IRB920_6kg_550_180_STD">

<link name="base_link">
  <inertial>
    <origin xyz="-0.027673827537510368 -0.0026803255602852526 0.0942820642453871" rpy="0 0 0"/>
    <mass value="41.12591553669811"/>
    <inertia ixx="0.263418" iyy="0.182723" izz="0.209732" ixy="-5.3e-05" iyz="-0.005906" ixz="2e-06"/>
  </inertial>
  <visual>
    <origin xyz="0 0 0" rpy="0 0 0"/>
    <geometry>
      <mesh filename="meshes/base_link.stl" scale="0.001 0.001 0.001"/>
    </geometry>
  </visual>
  <collision>
    <origin xyz="0 0 0" rpy="0 0 0"/>
    <geometry>
      <mesh filename="meshes/base_link.stl" scale="0.001 0.001 0.001"/>
    </geometry>
  </collision>
</link>

<link name="link_1">
  <inertial>
    <origin xyz="1.284644156949663e-05 -0.12564877114131737 0.0457295127124778" rpy="0 0 0"/>
    <mass value="32.62635723576266"/>
    <inertia ixx="0.484729" iyy="0.06875" izz="0.525248" ixy="-1.7e-05" iyz="0.020761" ixz="1.5e-05"/>
  </inertial>
  <visual>
    <origin xyz="0.027677 0.027437 -0.1914" rpy="0 0 0"/>
    <geometry>
      <mesh filename="meshes/link_1.stl" scale="0.001 0.001 0.001"/>
    </geometry>
  </visual>
  <collision>
    <origin xyz="0.027677 0.027437 -0.1914" rpy="0 0 0"/>
    <geometry>
      <mesh filename="meshes/link_1.stl" scale="0.001 0.001 0.001"/>
    </geometry>
  </collision>
</link>

<link name="link_2">
  <inertial>
    <origin xyz="2.9556487467288783e-06 -0.09936803691337931 0.0836813784830957" rpy="0 0 0"/>
    <mass value="75.77408460894007"/>
    <inertia ixx="1.206999" iyy="0.309324" izz="1.132456" ixy="-1.3e-05" iyz="-0.072376" ixz="1.8e-05"/>
  </inertial>
  <visual>
    <origin xyz="0.027677 0.317437 -0.2774" rpy="0 0 0"/>
    <geometry>
      <mesh filename="meshes/link_2.stl" scale="0.001 0.001 0.001"/>
    </geometry>
  </visual>
  <collision>
    <origin xyz="0.027677 0.317437 -0.2774" rpy="0 0 0"/>
    <geometry>
      <mesh filename="meshes/link_2.stl" scale="0.001 0.001 0.001"/>
    </geometry>
  </collision>
</link>

<link name="link_3">
  <inertial>
    <origin xyz="-7.441273095163889e-05 7.513882589227361e-05 0.16549531801456768" rpy="0 0 0"/>
    <mass value="0.6594614836495646"/>
    <inertia ixx="0.011651" iyy="0.011651" izz="7.7e-05" ixy="-1e-06" iyz="-1e-06" ixz="-0.0"/>
  </inertial>
  <visual>
    <origin xyz="0.027677 0.577437 -0.2414" rpy="0 0 0"/>
    <geometry>
      <mesh filename="meshes/link_3.stl" scale="0.001 0.001 0.001"/>
    </geometry>
  </visual>
  <collision>
    <origin xyz="0.027677 0.577437 -0.2414" rpy="0 0 0"/>
    <geometry>
      <mesh filename="meshes/link_3.stl" scale="0.001 0.001 0.001"/>
    </geometry>
  </collision>
</link>

<joint name="joint_1" type="continuous">
  <origin xyz="-0.027677 -0.027437 0.1914" rpy="0 0 0"/>
  <parent link="base_link"/>
  <child link="link_1"/>
  <axis xyz="0.0 0.0 1.0"/>
  <limit lower="-2.61799" upper="2.61799" effort="0.0" velocity="0.0"/>
</joint>

<joint name="joint_2" type="continuous">
  <origin xyz="0.0 -0.29 0.086" rpy="0 0 0"/>
  <parent link="link_1"/>
  <child link="link_2"/>
  <axis xyz="0.0 0.0 1.0"/>
  <limit lower="-2.53073" upper="2.53073" effort="0.0" velocity="0.0"/>
</joint>

<joint name="joint_3" type="prismatic">
  <origin xyz="0.0 -0.26 -0.036" rpy="0 0 0"/>
  <parent link="link_2"/>
  <child link="link_3"/>
  <axis xyz="-0.0 -0.0 -1.0"/>
  <limit lower="0.0" upper="0.145" effort="0.0" velocity="0.0"/>
</joint>

<link name="flange">
  <inertial>
    <origin xyz="0 0 0" rpy="0 0 0"/>
    <mass value="0.1"/>
    <inertia ixx="0.001" iyy="0.001" izz="0.001" ixy="0" iyz="0" ixz="0"/>
  </inertial>
</link>

<link name="tool0">
  <inertial>
    <origin xyz="0 0 0" rpy="0 0 0"/>
    <mass value="0.1"/>
    <inertia ixx="0.001" iyy="0.001" izz="0.001" ixy="0" iyz="0" ixz="0"/>
  </inertial>
</link>

<joint name="joint_4" type="continuous">
  <origin xyz="0 0 0" rpy="0 0 0"/>
  <parent link="link_3"/>
  <child link="flange"/>
  <axis xyz="0.0 0.0 1.0"/>
  <limit lower="-6.98132" upper="6.98132" effort="0.0" velocity="0.0"/>
</joint>

<joint name="joint_tool0" type="fixed">
  <origin xyz="0.0 0.0 0.0" rpy="0 0 0"/>
  <parent link="flange"/>
  <child link="tool0"/>
</joint>

</robot>