<?xml version="1.0" ?>
<robot name="IRB" xmlns:xacro="http://www.ros.org/wiki/xacro">

<xacro:include filename="$(find IRB_description)/urdf/materials.xacro" />
<xacro:include filename="$(find IRB_description)/urdf/IRB.trans" />
<xacro:include filename="$(find IRB_description)/urdf/IRB.gazebo" />
<link name="base_link">
  <inertial>
    <origin xyz="-0.03428217335737813 -2.4667588020476706e-07 0.08971070325608167" rpy="0 0 0"/>
    <mass value="47.926347738289834"/>
    <inertia ixx="0.305149" iyy="0.354553" izz="0.217137" ixy="-4e-06" iyz="9.8e-05" ixz="0.004008"/>
  </inertial>
  <visual>
    <origin xyz="0 0 0" rpy="0 0 0"/>
    <geometry>
      <mesh filename="package://IRB_description/meshes/base_link.stl" scale="0.001 0.001 0.001"/>
    </geometry>
    <material name="silver"/>
  </visual>
  <collision>
    <origin xyz="0 0 0" rpy="0 0 0"/>
    <geometry>
      <mesh filename="package://IRB_description/meshes/base_link.stl" scale="0.001 0.001 0.001"/>
    </geometry>
  </collision>
</link>

<link name="Link1_C350_IP54CR_1">
  <inertial>
    <origin xyz="0.11275513176109886 1.7513838112814044e-05 -0.0951509538380555" rpy="0 0 0"/>
    <mass value="33.86232074637399"/>
    <inertia ixx="0.142639" iyy="0.278472" izz="0.206182" ixy="2.3e-05" iyz="-2.8e-05" ixz="0.067431"/>
  </inertial>
  <visual>
    <origin xyz="-0.0 -4e-06 0.0225" rpy="0 0 0"/>
    <geometry>
      <mesh filename="package://IRB_description/meshes/Link1_C350_IP54CR_1.stl" scale="0.001 0.001 0.001"/>
    </geometry>
    <material name="silver"/>
  </visual>
  <collision>
    <origin xyz="-0.0 -4e-06 0.0225" rpy="0 0 0"/>
    <geometry>
      <mesh filename="package://IRB_description/meshes/Link1_C350_IP54CR_1.stl" scale="0.001 0.001 0.001"/>
    </geometry>
  </collision>
</link>

<link name="Link2_C350_IP54CR_1">
  <inertial>
    <origin xyz="-0.07748210763311644 2.4149022072988045e-05 -0.08074925775211947" rpy="0 0 0"/>
    <mass value="36.19533232147432"/>
    <inertia ixx="0.105427" iyy="0.262885" izz="0.242365" ixy="-1e-06" iyz="-3.7e-05" ixz="-0.014601"/>
  </inertial>
  <visual>
    <origin xyz="-0.174731 0.0 0.228" rpy="0 0 0"/>
    <geometry>
      <mesh filename="package://IRB_description/meshes/Link2_C350_IP54CR_1.stl" scale="0.001 0.001 0.001"/>
    </geometry>
    <material name="silver"/>
  </visual>
  <collision>
    <origin xyz="-0.174731 0.0 0.228" rpy="0 0 0"/>
    <geometry>
      <mesh filename="package://IRB_description/meshes/Link2_C350_IP54CR_1.stl" scale="0.001 0.001 0.001"/>
    </geometry>
  </collision>
</link>

<link name="Link4_C350_IP54CR_1">
  <inertial>
    <origin xyz="2.217347784446274e-06 -6.636237422544021e-06 -0.13387670086396194" rpy="0 0 0"/>
    <mass value="0.7548467951787753"/>
    <inertia ixx="0.011663" iyy="0.011663" izz="9.1e-05" ixy="0.0" iyz="-0.0" ixz="0.0"/>
  </inertial>
  <visual>
    <origin xyz="0.0 -7e-06 0.158" rpy="0 0 0"/>
    <geometry>
      <mesh filename="package://IRB_description/meshes/Link4_C350_IP54CR_1.stl" scale="0.001 0.001 0.001"/>
    </geometry>
    <material name="silver"/>
  </visual>
  <collision>
    <origin xyz="0.0 -7e-06 0.158" rpy="0 0 0"/>
    <geometry>
      <mesh filename="package://IRB_description/meshes/Link4_C350_IP54CR_1.stl" scale="0.001 0.001 0.001"/>
    </geometry>
  </collision>
</link>

<joint name="j1" type="continuous">
  <origin xyz="0.0 4e-06 -0.0225" rpy="0 0 0"/>
  <parent link="base_link"/>
  <child link="Link1_C350_IP54CR_1"/>
  <axis xyz="0.0 0.0 -1.0"/>
</joint>

<joint name="j2" type="continuous">
  <origin xyz="0.174731 -4e-06 -0.2055" rpy="0 0 0"/>
  <parent link="Link1_C350_IP54CR_1"/>
  <child link="Link2_C350_IP54CR_1"/>
  <axis xyz="0.0 0.0 -1.0"/>
</joint>

<joint name="j3" type="prismatic">
  <origin xyz="-0.174731 7e-06 0.07" rpy="0 0 0"/>
  <parent link="Link2_C350_IP54CR_1"/>
  <child link="Link4_C350_IP54CR_1"/>
  <axis xyz="0.0 0.0 1.0"/>
  <limit upper="0.0" lower="0.0" effort="100" velocity="100"/>
</joint>

</robot>
