<?xml version="1.0" ?>
<robot name="IRB52_7-1.2-Short" xmlns:xacro="http://www.ros.org/wiki/xacro">

<xacro:include filename="$(find IRB52_7-1.2-Short_description)/urdf/materials.xacro" />
<xacro:include filename="$(find IRB52_7-1.2-Short_description)/urdf/IRB52_7-1.2-Short.trans" />
<xacro:include filename="$(find IRB52_7-1.2-Short_description)/urdf/IRB52_7-1.2-Short.gazebo" />
<link name="base_link">
  <inertial>
    <origin xyz="-0.1003642789864372 0.0005070514200372364 0.06157262705526034" rpy="0 0 0"/>
    <mass value="226.44137740993105"/>
    <inertia ixx="3.83046" iyy="6.601434" izz="9.832628" ixy="0.01063" iyz="-0.008453" ixz="0.316423"/>
  </inertial>
  <visual>
    <origin xyz="0 0 0" rpy="0 0 0"/>
    <geometry>
      <mesh filename="package://IRB52_7-1.2-Short_description/meshes/base_link.stl" scale="0.001 0.001 0.001"/>
    </geometry>
    <material name="silver"/>
  </visual>
  <collision>
    <origin xyz="0 0 0" rpy="0 0 0"/>
    <geometry>
      <mesh filename="package://IRB52_7-1.2-Short_description/meshes/base_link.stl" scale="0.001 0.001 0.001"/>
    </geometry>
  </collision>
</link>

<link name="IRB52_short_T00F81B51V41H61_rev1_2_1">
  <inertial>
    <origin xyz="0.06548330296919894 0.031913732283330054 0.2349206888618654" rpy="0 0 0"/>
    <mass value="477.4224879733597"/>
    <inertia ixx="10.787614" iyy="16.559219" izz="13.533902" ixy="0.407137" iyz="0.480398" ixz="-1.612466"/>
  </inertial>
  <visual>
    <origin xyz="0.0 -0.0 -0.1245" rpy="0 0 0"/>
    <geometry>
      <mesh filename="package://IRB52_7-1.2-Short_description/meshes/IRB52_short_T00F81B51V41H61_rev1_2_1.stl" scale="0.001 0.001 0.001"/>
    </geometry>
    <material name="silver"/>
  </visual>
  <collision>
    <origin xyz="0.0 -0.0 -0.1245" rpy="0 0 0"/>
    <geometry>
      <mesh filename="package://IRB52_7-1.2-Short_description/meshes/IRB52_short_T00F81B51V41H61_rev1_2_1.stl" scale="0.001 0.001 0.001"/>
    </geometry>
  </collision>
</link>

<link name="IRB52_short_T00F81B51V41H61_rev1_3_1">
  <inertial>
    <origin xyz="-0.00015451427242296756 -0.04479212901171742 0.2019310492620799" rpy="0 0 0"/>
    <mass value="62.10839179243666"/>
    <inertia ixx="2.091669" iyy="2.134942" izz="0.160797" ixy="0.000255" iyz="-0.147584" ixz="-0.006539"/>
  </inertial>
  <visual>
    <origin xyz="-0.15 0.138 -0.4865" rpy="0 0 0"/>
    <geometry>
      <mesh filename="package://IRB52_7-1.2-Short_description/meshes/IRB52_short_T00F81B51V41H61_rev1_3_1.stl" scale="0.001 0.001 0.001"/>
    </geometry>
    <material name="silver"/>
  </visual>
  <collision>
    <origin xyz="-0.15 0.138 -0.4865" rpy="0 0 0"/>
    <geometry>
      <mesh filename="package://IRB52_7-1.2-Short_description/meshes/IRB52_short_T00F81B51V41H61_rev1_3_1.stl" scale="0.001 0.001 0.001"/>
    </geometry>
  </collision>
</link>

<link name="IRB52_short_T00F81B51V41H61_rev1_4_1">
  <inertial>
    <origin xyz="0.016914128190772176 0.1358229083196425 -0.013696029007024602" rpy="0 0 0"/>
    <mass value="137.98509508779952"/>
    <inertia ixx="1.05566" iyy="2.173418" izz="2.264468" ixy="0.107306" iyz="0.077811" ixz="-0.015508"/>
  </inertial>
  <visual>
    <origin xyz="-0.15 0.11 -0.9615" rpy="0 0 0"/>
    <geometry>
      <mesh filename="package://IRB52_7-1.2-Short_description/meshes/IRB52_short_T00F81B51V41H61_rev1_4_1.stl" scale="0.001 0.001 0.001"/>
    </geometry>
    <material name="silver"/>
  </visual>
  <collision>
    <origin xyz="-0.15 0.11 -0.9615" rpy="0 0 0"/>
    <geometry>
      <mesh filename="package://IRB52_7-1.2-Short_description/meshes/IRB52_short_T00F81B51V41H61_rev1_4_1.stl" scale="0.001 0.001 0.001"/>
    </geometry>
  </collision>
</link>

<link name="IRB52_short_T00F81B51V41H61_rev1_5_1">
  <inertial>
    <origin xyz="0.16574308075572902 -0.0009230813206154442 -0.0004499364710910392" rpy="0 0 0"/>
    <mass value="23.22858508249877"/>
    <inertia ixx="0.039958" iyy="0.214074" izz="0.222867" ixy="0.002898" iyz="5.2e-05" ixz="0.000407"/>
  </inertial>
  <visual>
    <origin xyz="-0.464 0.0 -0.9615" rpy="0 0 0"/>
    <geometry>
      <mesh filename="package://IRB52_7-1.2-Short_description/meshes/IRB52_short_T00F81B51V41H61_rev1_5_1.stl" scale="0.001 0.001 0.001"/>
    </geometry>
    <material name="silver"/>
  </visual>
  <collision>
    <origin xyz="-0.464 0.0 -0.9615" rpy="0 0 0"/>
    <geometry>
      <mesh filename="package://IRB52_7-1.2-Short_description/meshes/IRB52_short_T00F81B51V41H61_rev1_5_1.stl" scale="0.001 0.001 0.001"/>
    </geometry>
  </collision>
</link>

<link name="IRB52_short_T00F81B51V41H61_rev1_0_1">
  <inertial>
    <origin xyz="-4.440892098500626e-16 -0.01365000000000034 -1.1102230246251565e-15" rpy="0 0 0"/>
    <mass value="1.0387285866977913"/>
    <inertia ixx="0.000592" iyy="0.000958" izz="0.000508" ixy="0.0" iyz="0.0" ixz="-0.0"/>
  </inertial>
  <visual>
    <origin xyz="-0.75 -0.01365 -0.9615" rpy="0 0 0"/>
    <geometry>
      <mesh filename="package://IRB52_7-1.2-Short_description/meshes/IRB52_short_T00F81B51V41H61_rev1_0_1.stl" scale="0.001 0.001 0.001"/>
    </geometry>
    <material name="silver"/>
  </visual>
  <collision>
    <origin xyz="-0.75 -0.01365 -0.9615" rpy="0 0 0"/>
    <geometry>
      <mesh filename="package://IRB52_7-1.2-Short_description/meshes/IRB52_short_T00F81B51V41H61_rev1_0_1.stl" scale="0.001 0.001 0.001"/>
    </geometry>
  </collision>
</link>

<link name="IRB52_short_T00F81B51V41H61_rev1_7_1">
  <inertial>
    <origin xyz="0.0036397384431808844 -9.698639895149904e-08 -0.00019732680522110968" rpy="0 0 0"/>
    <mass value="0.2292693926024354"/>
    <inertia ixx="4.7e-05" iyy="0.000105" izz="0.000106" ixy="0.0" iyz="0.0" ixz="1e-06"/>
  </inertial>
  <visual>
    <origin xyz="-0.792004 0.0 -0.9615" rpy="0 0 0"/>
    <geometry>
      <mesh filename="package://IRB52_7-1.2-Short_description/meshes/IRB52_short_T00F81B51V41H61_rev1_7_1.stl" scale="0.001 0.001 0.001"/>
    </geometry>
    <material name="silver"/>
  </visual>
  <collision>
    <origin xyz="-0.792004 0.0 -0.9615" rpy="0 0 0"/>
    <geometry>
      <mesh filename="package://IRB52_7-1.2-Short_description/meshes/IRB52_short_T00F81B51V41H61_rev1_7_1.stl" scale="0.001 0.001 0.001"/>
    </geometry>
  </collision>
</link>

<joint name="Revolute 1" type="continuous">
  <origin xyz="0.0 0.0 0.1245" rpy="0 0 0"/>
  <parent link="base_link"/>
  <child link="IRB52_short_T00F81B51V41H61_rev1_2_1"/>
  <axis xyz="0.0 0.0 1.0"/>
</joint>

<joint name="Revolute 2" type="continuous">
  <origin xyz="0.15 -0.138 0.362" rpy="0 0 0"/>
  <parent link="IRB52_short_T00F81B51V41H61_rev1_2_1"/>
  <child link="IRB52_short_T00F81B51V41H61_rev1_3_1"/>
  <axis xyz="-0.0 -1.0 0.0"/>
</joint>

<joint name="Revolute 3" type="continuous">
  <origin xyz="0.0 0.028 0.475" rpy="0 0 0"/>
  <parent link="IRB52_short_T00F81B51V41H61_rev1_3_1"/>
  <child link="IRB52_short_T00F81B51V41H61_rev1_4_1"/>
  <axis xyz="0.0 -1.0 0.0"/>
</joint>

<joint name="Revolute 4" type="continuous">
  <origin xyz="0.314 0.11 0.0" rpy="0 0 0"/>
  <parent link="IRB52_short_T00F81B51V41H61_rev1_4_1"/>
  <child link="IRB52_short_T00F81B51V41H61_rev1_5_1"/>
  <axis xyz="1.0 0.0 0.0"/>
</joint>

<joint name="Revolute 5" type="continuous">
  <origin xyz="0.286 0.01365 0.0" rpy="0 0 0"/>
  <parent link="IRB52_short_T00F81B51V41H61_rev1_5_1"/>
  <child link="IRB52_short_T00F81B51V41H61_rev1_0_1"/>
  <axis xyz="0.0 1.0 0.0"/>
</joint>

<joint name="Revolute 6" type="continuous">
  <origin xyz="0.042004 -0.01365 0.0" rpy="0 0 0"/>
  <parent link="IRB52_short_T00F81B51V41H61_rev1_0_1"/>
  <child link="IRB52_short_T00F81B51V41H61_rev1_7_1"/>
  <axis xyz="1.0 0.0 0.0"/>
</joint>

</robot>
